Workbook

Sheet Regions
A1: No | B1: Category | C1: Region_tech_name | D1: Region_Code | E1: Region product name | F1: Country_Count | G1: Countries_ISO2 | H1: Countries | I1: Short_Explanation | K1: TOTAL
A2: 1 | B2: Main region | C2: GLOBAL | D2: =+_xlfn.XLOOKUP(C2,Codes!C:C,Codes!B:B,) -> GLBL | E2: Global | F2: 188 | G2: AD, AE, AF, AG, AI, AL, AM, AO, AR, AT, AU, AZ, BA, BB, BE, BG, BH, BM, BQ, BR, BS, BZ, BW, BY, CA, CD, CH, CL, CN, CO, CR, CU, CV, CY, CZ, DE, DK, DZ, EC, EE, EG, ES, ET, FI, FJ, FO, FR, GB, GE, GG, GH, GL, GM, GP, GR, GT, HK, HR, HU, ID, IE, IL, IN, IQ, IR, IS, IT, JE, JM, JO, JP, KE, KG, KH, KN, KR, KW, KY, KZ, LA, LB, LC, LI, LK, LR, LS, LT, LU, LV, LY, MA, MC, MD, ME, MK, ML, MO, MT, MU, MV, MX, MY, NG, NI, NL, NO, NP, NZ, OM, PA, PE, PF, PG, PH, PK, PL, PR, PT, PY, QA, RE, RO, RS, RU, RW, SA, SD, SE, SG, SI, SK, SL, SN, SR, SV, TC, TD, TG, TH, TJ, TN, TO, TR, TW, TZ, UA, US, UY, UZ, VE, VG, VN, XK, ZA, PW, AW, BD, BF, BJ, BN, BO, CI, CK, CM, DM, DO, GA, GD, GI, GN, GY, HT, MG, MN, MQ, MR, MS, MW, MZ, NA, PS, SC, ST, TL, UG, VC, WS, ZW | H2: Andorra, UAE, Afghanistan, Antigua and Barbuda, Anguilla, Albania, Armenia, Angola, Argentina, Austria, Australia, Azerbaijan, Bosnia and Herzegovina, Barbados, Belgium, Bulgaria, Bahrain, Bermuda, Netherlands Antilles, Brazil, Bahamas, Botswana, Belarus, Belize, Canada, Congo Kinshasa, Switzerland, Chile, China, Colombia, Costa Rica, Cuba, Cape Verde, Cyprus, Czech Republic, Germany, Denmark, Algeria, Ecuador, Estonia, Egypt, Spain, Ethiopia, Finland, Fiji, Faroe Islands, France, UK, Georgia, Channel Islands, Ghana, Greenland, Gambia, French West Indies, Greece, Guatemala, Hong Kong, Croatia, Hungary, Indonesia, Ireland, Israel, India, Iraq, Iran, Iceland, Italy, Channel Islands, Jamaica, Jordan, Japan, Kenya, Kyrgyzstan, Cambodia, Saint Kitts and Nevis, South Korea, Kuwait, Cayman Islands, Kazakhstan, Laos, Lebanon, Saint Lucia, Liechtenstein, Sri Lanka, Liberia, Lesotho, Lithuania, Luxembourg, Latvia, Libya, Morocco, Monaco, Moldova, Montenegro, North Macedonia, Mali, Macao, Malta, Mauritius, Maldives, Mexico, Malaysia, Nigeria, Nicaragua, Netherlands, Norway, Nepal, New Zealand, Oman, Panama, Peru, French Polynesia, Papua New Guinea, Philippines, Pakistan, Poland, Puerto Rico, Portugal, Paraguay, Qatar, Reunion, Romania, Serbia, Russia, Rwanda, Saudi Arabia, Sudan, Sweden, Singapore, Slovenia, Slovak Republic, Sierra Leone, Senegal, El Salvador, Turks and Caicos Islands, Chad, Togo, Thailand, Tajikistan, Tunisia, Tonga, Turkey, Taiwan, Tanzania, Ukraine, USA, Uruguay, Uzbekistan, Venezuela, British Virgin Islands, Vietnam, Kosovo, South Africa, Suriname, Palau, Aruba, Bangladesh, Burkina Faso, Benin, Brunei Darussalam, Bolivia, Cote d'Ivoire, Cook Islands, Cameroon, Dominica, Dominican Republic, Gabon, Grenada, Gibraltar, Guinea, Guyana, Haiti, Madagascar, Mongolia, Martinique, Mauritania, Montserrat, Malawi, Mozambique, Namibia, State of Palestine, Seychelles, Sao Tome and Principe, Timor-Leste, Uganda, Saint Vincent and the Grenadines, Samoa, Zimbabwe | I2: All available countries and territories from the restricted source list. | K2: =+COUNT(F2:F51)+F2 -> 238
A3: 2 | B3: Main region | C3: EUROPA | D3: =+_xlfn.XLOOKUP(C3,Codes!C:C,Codes!B:B,) -> EURP | E3: Europe | F3: 49 | G3: AD, AL, AT, BA, BE, BG, BY, CH, CY, CZ, DE, DK, EE, ES, FI, FO, FR, GB, GG, GR, HR, HU, IE, IS, IT, JE, LI, LT, LU, LV, MC, MD, ME, MK, MT, NL, NO, PL, PT, RO, RS, RU, SE, SI, SK, TR, UA, XK, GI | H3: Andorra, Albania, Austria, Bosnia and Herzegovina, Belgium, Bulgaria, Belarus, Switzerland, Cyprus, Czech Republic, Germany, Denmark, Estonia, Spain, Finland, Faroe Islands, France, UK, Channel Islands, Greece, Croatia, Hungary, Ireland, Iceland, Italy, Channel Islands, Liechtenstein, Lithuania, Luxembourg, Latvia, Monaco, Moldova, Montenegro, North Macedonia, Malta, Netherlands, Norway, Poland, Portugal, Romania, Serbia, Russia, Sweden, Slovenia, Slovak Republic, Turkey, Ukraine, Kosovo, Gibraltar | I3: Broad Europe package adapted to the restricted source list.
A4: 3 | B4: Main region | C4: EU_UK_NOR | D4: =+_xlfn.XLOOKUP(C4,Codes!C:C,Codes!B:B,) -> EUNR | E4: EU, UK & Norway | F4: 29 | G4: AT, BE, BG, HR, CY, CZ, DK, EE, FI, FR, DE, GR, HU, IE, IT, LV, LT, LU, MT, NL, PL, PT, RO, SK, SI, ES, SE, NO, GB | H4: Austria, Belgium, Bulgaria, Croatia, Cyprus, Czech Republic, Denmark, Estonia, Finland, France, Germany, Greece, Hungary, Ireland, Italy, Latvia, Lithuania, Luxembourg, Malta, Netherlands, Poland, Portugal, Romania, Slovak Republic, Slovenia, Spain, Sweden, Norway, UK | I4: EU-style regional bundle with United Kingdom and Norway.
A5: 4 | B5: Main region | C5: NORTH_AMERICA | D5: =+_xlfn.XLOOKUP(C5,Codes!C:C,Codes!B:B,) -> NOAM | E5: North America | F5: 3 | G5: CA, MX, US | H5: Canada, Mexico, USA | I5: Broad North America package.
A6: 5 | B6: Main region | C6: MENA | D6: =+_xlfn.XLOOKUP(C6,Codes!C:C,Codes!B:B,) -> MENA | E6: Middle East & North Africa | F6: 16 | G6: AE, BH, EG, IQ, IL, IR, JO, KW, LB, LY, MA, OM, QA, SA, TN, PS | H6: UAE, Bahrain, Egypt, Iraq, Israel, Iran, Jordan, Kuwait, Lebanon, Libya, Morocco, Oman, Qatar, Saudi Arabia, Tunisia, State of Palestine | I6: Middle East and North Africa bundle using only available countries.
A7: 6 | B7: Main region | C7: AFRICA | D7: =+_xlfn.XLOOKUP(C7,Codes!C:C,Codes!B:B,) -> AFRI | E7: Africa | F7: 42 | G7: AO, BW, CD, CV, DZ, EG, ET, GH, GM, KE, LR, LS, LY, MA, ML, MU, NG, RE, RW, SD, SL, SN, TD, TG, TN, TZ, ZA, BF, BJ, CI, CM, GA, GN, MG, MR, MW, MZ, NA, SC, ST, UG, ZW | H7: Angola, Botswana, Congo Kinshasa, Cape Verde, Algeria, Egypt, Ethiopia, Ghana, Gambia, Kenya, Liberia, Lesotho, Libya, Morocco, Mali, Mauritius, Nigeria, Reunion, Rwanda, Sudan, Sierra Leone, Senegal, Chad, Togo, Tunisia, Tanzania, South Africa, Burkina Faso, Benin, Cote d'Ivoire, Cameroon, Gabon, Guinea, Madagascar, Mauritania, Malawi, Mozambique, Namibia, Seychelles, Sao Tome and Principe, Uganda, Zimbabwe | I7: Broad Africa package using the available restricted country list.
A8: 7 | B8: Main region | C8: LATAM | D8: =+_xlfn.XLOOKUP(C8,Codes!C:C,Codes!B:B,) -> LATM | E8: Latin America | F8: 20 | G8: AR, BR, CL, CO, CR, CU, EC, GT, MX, NI, PA, PE, PY, SV, UY, VE, SR, BZ, BO, GY | H8: Argentina, Brazil, Chile, Colombia, Costa Rica, Cuba, Ecuador, Guatemala, Mexico, Nicaragua, Panama, Peru, Paraguay, El Salvador, Uruguay, Venezuela, Suriname, Belize, Bolivia, Guyana | I8: Latin America / LATAM extended bundle; Mexico is kept here as a commercial LATAM variant.
A9: 8 | B9: Main region | C9: OCEANIA | D9: =+_xlfn.XLOOKUP(C9,Codes!C:C,Codes!B:B,) -> OCEA | E9: Oceania & Pacific | F9: 9 | G9: AU, FJ, NZ, PF, PG, TO, PW, CK, WS | H9: Australia, Fiji, New Zealand, French Polynesia, Papua New Guinea, Tonga, Palau, Cook Islands, Samoa | I9: Broad Oceania and Pacific package based on the source list.
A10: 9 | B10: Main region | C10: ASIA | D10: =+_xlfn.XLOOKUP(C10,Codes!C:C,Codes!B:B,) -> ASIA | E10: Asia | F10: 32 | G10: AF, AM, AZ, CN, GE, HK, ID, IN, IR, IQ, JP, KG, KH, KR, KZ, LA, LK, MO, MY, NP, PH, PK, SG, TH, TJ, TW, UZ, VN, BD, BN, MN, TL | H10: Afghanistan, Armenia, Azerbaijan, China, Georgia, Hong Kong, Indonesia, India, Iran, Iraq, Japan, Kyrgyzstan, Cambodia, South Korea, Kazakhstan, Laos, Sri Lanka, Macao, Malaysia, Nepal, Philippines, Pakistan, Singapore, Thailand, Tajikistan, Taiwan, Uzbekistan, Vietnam, Bangladesh, Brunei Darussalam, Mongolia, Timor-Leste | I10: Broad Asia package using available countries.
A11: 10 | B11: Main region | C11: CARIBBEAN | D11: =+_xlfn.XLOOKUP(C11,Codes!C:C,Codes!B:B,) -> CARB | E11: Caribbean | F11: 25 | G11: AG, AI, BB, BM, BQ, BS, CU, GP, JM, KN, KY, LC, PR, TC, SR, VG, BZ, AW, DM, DO, GD, HT, MQ, MS, VC | H11: Antigua and Barbuda, Anguilla, Barbados, Bermuda, Netherlands Antilles, Bahamas, Cuba, French West Indies, Jamaica, Saint Kitts and Nevis, Cayman Islands, Saint Lucia, Puerto Rico, Turks and Caicos Islands, British Virgin Islands, Suriname, Belize, Aruba, Dominica, Dominican Republic, Grenada, Haiti, Martinique, Montserrat, Saint Vincent and the Grenadines | I11: Caribbean and nearby island markets available in the restricted list.
A12: 11 | B12: Additional Europe travel region | C12: SE_EUROPE | D12: =+_xlfn.XLOOKUP(C12,Codes!C:C,Codes!B:B,) -> SEEU | E12: Southeast Europe | F12: 10 | G12: GR, RO, BG, HR, RS, BA, AL, ME, MK, XK | H12: Greece, Romania, Bulgaria, Croatia, Serbia, Bosnia and Herzegovina, Albania, Montenegro, North Macedonia, Kosovo | I12: Wider Southeast Europe bundle including EU and non-EU Balkan markets.
A13: 12 | B13: Additional Europe travel region | C13: WEST_BALKANS | D13: =+_xlfn.XLOOKUP(C13,Codes!C:C,Codes!B:B,) -> WBAL | E13: Western Balkans | F13: 7 | G13: HR, BA, RS, ME, AL, MK, XK | H13: Croatia, Bosnia and Herzegovina, Serbia, Montenegro, Albania, North Macedonia, Kosovo | I13: Western Balkans cluster without Greece, Romania and Bulgaria.
A14: 13 | B14: Additional Europe travel region | C14: ADRIATIC | D14: =+_xlfn.XLOOKUP(C14,Codes!C:C,Codes!B:B,) -> ADRI | E14: Adriatic Coast | F14: 5 | G14: IT, SI, HR, ME, AL | H14: Italy, Slovenia, Croatia, Montenegro, Albania | I14: Adriatic coast holiday, road-trip and cruise corridor.
... A51: 50 | B51: Additional Oceania travel region | C51: PACIFIC_LONG_HAUL | D51: =+_xlfn.XLOOKUP(C51,Codes!C:C,Codes!B:B,) -> PLON | E51: Pacific Explorer | F51: 9 | G51: AU, NZ, FJ, PF, PG, TO, PW, CK, WS | H51: Australia, New Zealand, Fiji, French Polynesia, Papua New Guinea, Tonga, Palau, Cook Islands, Samoa | I51: Long-haul Oceania and Pacific travel bundle.

Sheet Codes
A1: No | B1: Region_Codes | C1: Region_tech_name | D1: region_type | E1: Region product name | F1: en | G1: hr | H1: de | I1: fr | J1: ja | K1: it | L1: es | M1: pt | O1: Check
A2: =+_xlfn.XLOOKUP(B2,Regions!D:D,Regions!A:A) -> 1 | B2: GLBL | C2: GLOBAL | D2: GLOBAL | E2: =+_xlfn.XLOOKUP(C2,Regions!C:C,Regions!E:E,) -> Global | F2: Global | G2: Global | H2: Global | I2: Monde | J2: グローバル | K2: Globale | L2: Global | M2: Global | N2: Global | O2: Global
A3: =+_xlfn.XLOOKUP(B3,Regions!D:D,Regions!A:A) -> 2 | B3: EURP | C3: EUROPA | D3: LARGE_REGION | E3: =+_xlfn.XLOOKUP(C3,Regions!C:C,Regions!E:E,) -> Europe | F3: Europe | G3: Europa | H3: Europa | I3: Europe | J3: ヨーロッパ | K3: Europa | L3: Europa | M3: Europa | N3: Europe | O3: Europa
A4: =+_xlfn.XLOOKUP(B4,Regions!D:D,Regions!A:A) -> 3 | B4: EUNR | C4: EU_UK_NOR | D4: LARGE_REGION | E4: =+_xlfn.XLOOKUP(C4,Regions!C:C,Regions!E:E,) -> EU, UK & Norway | F4: EU, UK & Norway | G4: EU, UK i Norveška | H4: EU, UK & Norwegen | I4: UE, Royaume-Uni et Norvège | J4: EU・英国・ノルウェー | K4: UE, Regno Unito e Norvegia | L4: UE, Reino Unido y Noruega | M4: UE, Reino Unido e Noruega | N4: EU, UK & Norway | O4: EU, UK i Norveška
A5: =+_xlfn.XLOOKUP(B5,Regions!D:D,Regions!A:A) -> 4 | B5: NOAM | C5: NORTH_AMERICA | D5: LARGE_REGION | E5: =+_xlfn.XLOOKUP(C5,Regions!C:C,Regions!E:E,) -> North America | F5: North America | G5: Sjeverna Amerika | H5: Nordamerika | I5: Amérique du Nord | J5: 北アメリカ | K5: Nord America | L5: Norteamérica | M5: América do Norte | N5: North America | O5: Sjeverna Amerika
A6: =+_xlfn.XLOOKUP(B6,Regions!D:D,Regions!A:A) -> 5 | B6: MENA | C6: MENA | D6: LARGE_REGION | E6: =+_xlfn.XLOOKUP(C6,Regions!C:C,Regions!E:E,) -> Middle East & North Africa | F6: Middle East & North Africa | G6: Bliski istok i Sjeverna Afrika | H6: Naher Osten & Nordafrika | I6: Moyen-Orient et Afrique du Nord | J6: 中東・北アフリカ | K6: Medio Oriente e Nord Africa | L6: Oriente Medio y Norte de África | M6: Oriente Médio e Norte da África | N6: Middle East & North Africa | O6: Bliski istok i Sjeverna Afrika
A7: =+_xlfn.XLOOKUP(B7,Regions!D:D,Regions!A:A) -> 6 | B7: AFRI | C7: AFRICA | D7: LARGE_REGION | E7: =+_xlfn.XLOOKUP(C7,Regions!C:C,Regions!E:E,) -> Africa | F7: Africa | G7: Afrika | H7: Afrika | I7: Afrique | J7: アフリカ | K7: Africa | L7: África | M7: África | N7: Africa | O7: Afrika
A8: =+_xlfn.XLOOKUP(B8,Regions!D:D,Regions!A:A) -> 7 | B8: LATM | C8: LATAM | D8: LARGE_REGION | E8: =+_xlfn.XLOOKUP(C8,Regions!C:C,Regions!E:E,) -> Latin America | F8: Latin America | G8: Latinska Amerika | H8: Lateinamerika | I8: Amérique latine | J8: ラテンアメリカ | K8: America Latina | L8: América Latina | M8: América Latina | N8: Latin America | O8: Latinska Amerika
A9: =+_xlfn.XLOOKUP(B9,Regions!D:D,Regions!A:A) -> 8 | B9: OCEA | C9: OCEANIA | D9: LARGE_REGION | E9: =+_xlfn.XLOOKUP(C9,Regions!C:C,Regions!E:E,) -> Oceania & Pacific | F9: Oceania & Pacific | G9: Oceanija i Pacifik | H9: Ozeanien & Pazifik | I9: Océanie et Pacifique | J9: オセアニア・太平洋 | K9: Oceania e Pacifico | L9: Oceanía y Pacífico | M9: Oceania e Pacífico | N9: Oceania & Pacific | O9: Oceanija i Pacifik
A10: =+_xlfn.XLOOKUP(B10,Regions!D:D,Regions!A:A) -> 9 | B10: ASIA | C10: ASIA | D10: LARGE_REGION | E10: =+_xlfn.XLOOKUP(C10,Regions!C:C,Regions!E:E,) -> Asia | F10: Asia | G10: Azija | H10: Asien | I10: Asie | J10: アジア | K10: Asia | L10: Asia | M10: Ásia | N10: Asia | O10: Azija
A11: =+_xlfn.XLOOKUP(B11,Regions!D:D,Regions!A:A) -> 10 | B11: CARB | C11: CARIBBEAN | D11: LARGE_REGION | E11: =+_xlfn.XLOOKUP(C11,Regions!C:C,Regions!E:E,) -> Caribbean | F11: Caribbean | G11: Karibi | H11: Karibik | I11: Caraïbes | J11: カリブ海 | K11: Caraibi | L11: Caribe | M11: Caribe | N11: Caribbean | O11: Karibi
A12: =+_xlfn.XLOOKUP(B12,Regions!D:D,Regions!A:A) -> 11 | B12: SEEU | C12: SE_EUROPE | D12: MEDIUM_REGION | E12: =+_xlfn.XLOOKUP(C12,Regions!C:C,Regions!E:E,) -> Southeast Europe | F12: Southeast Europe | G12: Jugoistočna Europa | H12: Südosteuropa | I12: Europe du Sud-Est | J12: 南東ヨーロッパ | K12: Europa sud-orientale | L12: Europa sudoriental | M12: Sudeste da Europa | N12: Southeast Europe | O12: Jugoistočna Europa
A13: =+_xlfn.XLOOKUP(B13,Regions!D:D,Regions!A:A) -> 12 | B13: WBAL | C13: WEST_BALKANS | D13: MEDIUM_REGION | E13: =+_xlfn.XLOOKUP(C13,Regions!C:C,Regions!E:E,) -> Western Balkans | F13: Western Balkans | G13: Zapadni Balkan | H13: Westbalkan | I13: Balkans occidentaux | J13: 西バルカン | K13: Balcani occidentali | L13: Balcanes occidentales | M13: Balcãs Ocidentais | N13: Western Balkans | O13: Zapadni Balkan
... A32: =+_xlfn.XLOOKUP(B32,Regions!D:D,Regions!A:A) -> 31 | B32: JKTW | C32: JP_KR_TW | D32: MEDIUM_REGION | E32: =+_xlfn.XLOOKUP(C32,Regions!C:C,Regions!E:E,) -> Japan, South Korea & Taiwan | F32: Japan, South Korea & Taiwan | G32: Japan, Južna Koreja i Tajvan | H32: Japan, Südkorea & Taiwan | I32: Japon, Corée du Sud et Taïwan | J32: 日本・韓国・台湾 | K32: Giappone, Corea del Sud e Taiwan | L32: Japón, Corea del Sur y Taiwán | M32: Japão, Coreia do Sul e Taiwan | N32: Japan, South Korea & Taiwan | O32: Japan, Južna Koreja i Tajvan
A33: =+_xlfn.XLOOKUP(B33,Regions!D:D,Regions!A:A) -> 32 | B33: SUBC | C33: SUBCONTINENT | D33: MEDIUM_REGION | E33: =+_xlfn.XLOOKUP(C33,Regions!C:C,Regions!E:E,) -> Indian Subcontinent | F33: Indian Subcontinent | G33: Indijski potkontinent | H33: Indischer Subkontinent | I33: Sous-continent indien | J33: インド亜大陸 | K33: Subcontinente indiano | L33: Subcontinente indio | M33: Subcontinente indiano | N33: #N/A | O33: Indijski potkontinent
A34: =+_xlfn.XLOOKUP(B34,Regions!D:D,Regions!A:A) -> 33 | B34: NAFR | C34: NORTH_AFRICA | D34: MEDIUM_REGION | E34: =+_xlfn.XLOOKUP(C34,Regions!C:C,Regions!E:E,) -> North Africa | F34: North Africa | G34: Sjeverna Afrika | H34: Nordafrika | I34: Afrique du Nord | J34: 北アフリカ | K34: Nord Africa | L34: Norte de África | M34: Norte da África | N34: North Africa | O34: Sjeverna Afrika
A35: =+_xlfn.XLOOKUP(B35,Regions!D:D,Regions!A:A) -> 34 | B35: EAFR | C35: EAST_AFRICA | D35: MEDIUM_REGION | E35: =+_xlfn.XLOOKUP(C35,Regions!C:C,Regions!E:E,) -> East Africa | F35: East Africa | G35: Istočna Afrika | H35: Ostafrika | I35: Afrique de l’Est | J35: 東アフリカ | K35: Africa orientale | L35: África Oriental | M35: África Oriental | N35: East Africa | O35: Istočna Afrika
A36: =+_xlfn.XLOOKUP(B36,Regions!D:D,Regions!A:A) -> 35 | B36: SAFR | C36: SOUTHERN_AFRICA | D36: MEDIUM_REGION | E36: =+_xlfn.XLOOKUP(C36,Regions!C:C,Regions!E:E,) -> Southern Africa | F36: Southern Africa | G36: Južna Afrika | H36: Südliches Afrika | I36: Afrique australe | J36: 南部アフリカ | K36: Africa australe | L36: África Austral | M36: África Austral | N36: Southern Africa | O36: Južna Afrika
A37: =+_xlfn.XLOOKUP(B37,Regions!D:D,Regions!A:A) -> 36 | B37: WAFR | C37: WEST_AFRICA | D37: MEDIUM_REGION | E37: =+_xlfn.XLOOKUP(C37,Regions!C:C,Regions!E:E,) -> West Africa | F37: West Africa | G37: Zapadna Afrika | H37: Westafrika | I37: Afrique de l’Ouest | J37: 西アフリカ | K37: Africa occidentale | L37: África Occidental | M37: África Ocidental | N37: West Africa | O37: Zapadna Afrika
A38: =+_xlfn.XLOOKUP(B38,Regions!D:D,Regions!A:A) -> 37 | B38: SAFI | C38: AFRICA_SAFARI | D38: MEDIUM_REGION | E38: =+_xlfn.XLOOKUP(C38,Regions!C:C,Regions!E:E,) -> African Safari | F38: African Safari | G38: Afrički safari | H38: Afrika-Safari | I38: Safari africain | J38: アフリカンサファリ | K38: Safari africano | L38: Safari africano | M38: Safári africano | N38: African Safari | O38: Afrički safari
A39: =+_xlfn.XLOOKUP(B39,Regions!D:D,Regions!A:A) -> 38 | B39: INOC | C39: INDIAN_OCEAN | D39: MEDIUM_REGION | E39: =+_xlfn.XLOOKUP(C39,Regions!C:C,Regions!E:E,) -> Indian Ocean Islands | F39: Indian Ocean Islands | G39: Otoci Indijskog oceana | H39: Inseln im Indischen Ozean | I39: Îles de l’océan Indien | J39: インド洋の島々 | K39: Isole dell’Oceano Indiano | L39: Islas del océano Índico | M39: Ilhas do Oceano Índico | N39: #N/A | O39: Otoci Indijskog oceana
A40: =+_xlfn.XLOOKUP(B40,Regions!D:D,Regions!A:A) -> 39 | B40: CAFR | C40: CENTRAL_AFRICA | D40: MEDIUM_REGION | E40: =+_xlfn.XLOOKUP(C40,Regions!C:C,Regions!E:E,) -> Central Africa | F40: Central Africa | G40: Srednja Afrika | H40: Zentralafrika | I40: Afrique centrale | J40: 中央アフリカ | K40: Africa centrale | L40: África Central | M40: África Central | N40: #N/A | O40: Srednja Afrika
A41: =+_xlfn.XLOOKUP(B41,Regions!D:D,Regions!A:A) -> 40 | B41: CAMR | C41: CENTRAL_AMERICA | D41: MEDIUM_REGION | E41: =+_xlfn.XLOOKUP(C41,Regions!C:C,Regions!E:E,) -> Central America | F41: Central America | G41: Srednja Amerika | H41: Mittelamerika | I41: Amérique centrale | J41: 中央アメリカ | K41: America centrale | L41: Centroamérica | M41: América Central | N41: Central America | O41: Srednja Amerika
A42: =+_xlfn.XLOOKUP(B42,Regions!D:D,Regions!A:A) -> 41 | B42: SAMR | C42: SOUTH_AMERICA | D42: MEDIUM_REGION | E42: =+_xlfn.XLOOKUP(C42,Regions!C:C,Regions!E:E,) -> South America | F42: South America | G42: Južna Amerika | H42: Südamerika | I42: Amérique du Sud | J42: 南アメリカ | K42: Sud America | L42: Sudamérica | M42: América do Sul | N42: South America | O42: Južna Amerika
A43: =+_xlfn.XLOOKUP(B43,Regions!D:D,Regions!A:A) -> 42 | B43: ANDS | C43: ANDEAN | D43: MEDIUM_REGION | E43: =+_xlfn.XLOOKUP(C43,Regions!C:C,Regions!E:E,) -> Andean Region | F43: Andean Region | G43: Andska regija | H43: Andenregion | I43: Région andine | J43: アンデス地域 | K43: Regione andina | L43: Región andina | M43: Região dos Andes | N43: Andean Region | O43: Andska regija
A44: =+_xlfn.XLOOKUP(B44,Regions!D:D,Regions!A:A) -> 43 | B44: SCON | C44: SOUTH_CONE | D44: MEDIUM_REGION | E44: =+_xlfn.XLOOKUP(C44,Regions!C:C,Regions!E:E,) -> Southern South America | F44: Southern South America | G44: Južni dio Južne Amerike | H44: Südliches Südamerika | I44: Amérique du Sud méridionale | J44: 南部南アメリカ | K44: Sud del Sud America | L44: Sur de Sudamérica | M44: Sul da América do Sul | N44: Southern South America | O44: Južni dio Južne Amerike
A45: =+_xlfn.XLOOKUP(B45,Regions!D:D,Regions!A:A) -> 44 | B45: CCRU | C45: CARIBBEAN_CRUISE | D45: MEDIUM_REGION | E45: =+_xlfn.XLOOKUP(C45,Regions!C:C,Regions!E:E,) -> Caribbean Cruise | F45: Caribbean Cruise | G45: Karipsko krstarenje | H45: Karibik-Kreuzfahrt | I45: Croisière dans les Caraïbes | J45: カリブ海クルーズ | K45: Crociera ai Caraibi | L45: Crucero por el Caribe | M45: Cruzeiro pelo Caribe | N45: Caribbean Cruise | O45: Karipsko krstarenje
A46: =+_xlfn.XLOOKUP(B46,Regions!D:D,Regions!A:A) -> 45 | B46: LANT | C46: LESSER_ANTILLES | D46: MEDIUM_REGION | E46: =+_xlfn.XLOOKUP(C46,Regions!C:C,Regions!E:E,) -> Lesser Antilles | F46: Lesser Antilles | G46: Mali Antili | H46: Kleine Antillen | I46: Petites Antilles | J46: 小アンティル諸島 | K46: Piccole Antille | L46: Antillas Menores | M46: Pequenas Antilhas | N46: Lesser Antilles | O46: Mali Antili
A47: =+_xlfn.XLOOKUP(B47,Regions!D:D,Regions!A:A) -> 46 | B47: NATL | C47: NORTH_ATLANTIC_ISLANDS | D47: MEDIUM_REGION | E47: =+_xlfn.XLOOKUP(C47,Regions!C:C,Regions!E:E,) -> North Atlantic Islands | F47: North Atlantic Islands | G47: Sjevernoatlantski otoci | H47: Nordatlantische Inseln | I47: Îles de l’Atlantique Nord | J47: 北大西洋の島々 | K47: Isole del Nord Atlantico | L47: Islas del Atlántico Norte | M47: Ilhas do Atlântico Norte | N47: North Atlantic Islands | O47: Sjevernoatlantski otoci
A48: =+_xlfn.XLOOKUP(B48,Regions!D:D,Regions!A:A) -> 47 | B48: USCA | C48: USA_CANADA | D48: MEDIUM_REGION | E48: =+_xlfn.XLOOKUP(C48,Regions!C:C,Regions!E:E,) -> USA & Canada | F48: USA & Canada | G48: SAD i Kanada | H48: USA & Kanada | I48: États-Unis et Canada | J48: 米国・カナダ | K48: USA e Canada | L48: EE. UU. y Canadá | M48: Estados Unidos e Canadá | N48: USA & Canada | O48: SAD i Kanada
A49: =+_xlfn.XLOOKUP(B49,Regions!D:D,Regions!A:A) -> 48 | B49: AUNZ | C49: AUS_NZ | D49: MEDIUM_REGION | E49: =+_xlfn.XLOOKUP(C49,Regions!C:C,Regions!E:E,) -> Australia & New Zealand | F49: Australia & New Zealand | G49: Australija i Novi Zeland | H49: Australien & Neuseeland | I49: Australie et Nouvelle-Zélande | J49: オーストラリア・ニュージーランド | K49: Australia e Nuova Zelanda | L49: Australia y Nueva Zelanda | M49: Austrália e Nova Zelândia | N49: Australia & New Zealand | O49: Australija i Novi Zeland
A50: =+_xlfn.XLOOKUP(B50,Regions!D:D,Regions!A:A) -> 49 | B50: SPAC | C50: SOUTH_PACIFIC | D50: MEDIUM_REGION | E50: =+_xlfn.XLOOKUP(C50,Regions!C:C,Regions!E:E,) -> South Pacific | F50: South Pacific | G50: Južni Pacifik | H50: Südpazifik | I50: Pacifique Sud | J50: 南太平洋 | K50: Pacifico del Sud | L50: Pacífico Sur | M50: Pacífico Sul | N50: #N/A | O50: Južni Pacifik
A51: =+_xlfn.XLOOKUP(B51,Regions!D:D,Regions!A:A) -> 50 | B51: PLON | C51: PACIFIC_LONG_HAUL | D51: MEDIUM_REGION | E51: =+_xlfn.XLOOKUP(C51,Regions!C:C,Regions!E:E,) -> Pacific Explorer | F51: Pacific Explorer | G51: Pacific Explorer | H51: Pacific Explorer | I51: Pacific Explorer | J51: Pacific Explorer | K51: Pacific Explorer | L51: Pacific Explorer | M51: Pacific Explorer | N51: Pacific Explorer | O51: Pacific Explorer

Sheet Countries
A1: ISO2 | B1: Countries | C1: en | D1: hr | E1: de | F1: fr | G1: ja | H1: it | I1: es | J1: pt | K1: alias_en | L1: Check
A2: AF | B2: Afghanistan | C2: =+_xlfn.XLOOKUP($A2,MappingTable!$A:$A,MappingTable!B:B) -> Afghanistan | D2: =+_xlfn.XLOOKUP($A2,MappingTable!$A:$A,MappingTable!C:C) -> Afganistan | E2: =+_xlfn.XLOOKUP($A2,MappingTable!$A:$A,MappingTable!D:D) -> Afghanistan | F2: =+_xlfn.XLOOKUP($A2,MappingTable!$A:$A,MappingTable!E:E) -> Afghanistan | G2: =+_xlfn.XLOOKUP($A2,MappingTable!$A:$A,MappingTable!F:F) -> アフガニスタン | H2: =+_xlfn.XLOOKUP($A2,MappingTable!$A:$A,MappingTable!G:G) -> Afghanistan | I2: =+_xlfn.XLOOKUP($A2,MappingTable!$A:$A,MappingTable!H:H) -> Afganistán | J2: =+_xlfn.XLOOKUP($A2,MappingTable!$A:$A,MappingTable!I:I) -> Afeganistão
A3: AL | B3: Albania | C3: =+_xlfn.XLOOKUP(A3,MappingTable!A:A,MappingTable!B:B) -> Albania | D3: =+_xlfn.XLOOKUP($A3,MappingTable!$A:$A,MappingTable!C:C) -> Albanija | E3: =+_xlfn.XLOOKUP($A3,MappingTable!$A:$A,MappingTable!D:D) -> Albanien | F3: =+_xlfn.XLOOKUP($A3,MappingTable!$A:$A,MappingTable!E:E) -> Albanie | G3: =+_xlfn.XLOOKUP($A3,MappingTable!$A:$A,MappingTable!F:F) -> アルバニア | H3: =+_xlfn.XLOOKUP($A3,MappingTable!$A:$A,MappingTable!G:G) -> Albania | I3: =+_xlfn.XLOOKUP($A3,MappingTable!$A:$A,MappingTable!H:H) -> Albania | J3: =+_xlfn.XLOOKUP($A3,MappingTable!$A:$A,MappingTable!I:I) -> Albânia
A4: DZ | B4: Algeria | C4: =+_xlfn.XLOOKUP(A4,MappingTable!A:A,MappingTable!B:B) -> Algeria | D4: =+_xlfn.XLOOKUP($A4,MappingTable!$A:$A,MappingTable!C:C) -> Alžir | E4: =+_xlfn.XLOOKUP($A4,MappingTable!$A:$A,MappingTable!D:D) -> Algerien | F4: =+_xlfn.XLOOKUP($A4,MappingTable!$A:$A,MappingTable!E:E) -> Algérie | G4: =+_xlfn.XLOOKUP($A4,MappingTable!$A:$A,MappingTable!F:F) -> アルジェリア | H4: =+_xlfn.XLOOKUP($A4,MappingTable!$A:$A,MappingTable!G:G) -> Algeria | I4: =+_xlfn.XLOOKUP($A4,MappingTable!$A:$A,MappingTable!H:H) -> Argelia | J4: =+_xlfn.XLOOKUP($A4,MappingTable!$A:$A,MappingTable!I:I) -> Argélia
A5: AD | B5: Andorra | C5: =+_xlfn.XLOOKUP(A5,MappingTable!A:A,MappingTable!B:B) -> Andorra | D5: =+_xlfn.XLOOKUP($A5,MappingTable!$A:$A,MappingTable!C:C) -> Andora | E5: =+_xlfn.XLOOKUP($A5,MappingTable!$A:$A,MappingTable!D:D) -> Andorra | F5: =+_xlfn.XLOOKUP($A5,MappingTable!$A:$A,MappingTable!E:E) -> Andorre | G5: =+_xlfn.XLOOKUP($A5,MappingTable!$A:$A,MappingTable!F:F) -> アンドラ | H5: =+_xlfn.XLOOKUP($A5,MappingTable!$A:$A,MappingTable!G:G) -> Andorra | I5: =+_xlfn.XLOOKUP($A5,MappingTable!$A:$A,MappingTable!H:H) -> Andorra | J5: =+_xlfn.XLOOKUP($A5,MappingTable!$A:$A,MappingTable!I:I) -> Andorra
A6: AO | B6: Angola | C6: =+_xlfn.XLOOKUP(A6,MappingTable!A:A,MappingTable!B:B) -> Angola | D6: =+_xlfn.XLOOKUP($A6,MappingTable!$A:$A,MappingTable!C:C) -> Angola | E6: =+_xlfn.XLOOKUP($A6,MappingTable!$A:$A,MappingTable!D:D) -> Angola | F6: =+_xlfn.XLOOKUP($A6,MappingTable!$A:$A,MappingTable!E:E) -> Angola | G6: =+_xlfn.XLOOKUP($A6,MappingTable!$A:$A,MappingTable!F:F) -> アンゴラ | H6: =+_xlfn.XLOOKUP($A6,MappingTable!$A:$A,MappingTable!G:G) -> Angola | I6: =+_xlfn.XLOOKUP($A6,MappingTable!$A:$A,MappingTable!H:H) -> Angola | J6: =+_xlfn.XLOOKUP($A6,MappingTable!$A:$A,MappingTable!I:I) -> Angola
A7: AI | B7: Anguilla | C7: =+_xlfn.XLOOKUP(A7,MappingTable!A:A,MappingTable!B:B) -> Anguilla | D7: =+_xlfn.XLOOKUP($A7,MappingTable!$A:$A,MappingTable!C:C) -> Angvila | E7: =+_xlfn.XLOOKUP($A7,MappingTable!$A:$A,MappingTable!D:D) -> Anguilla | F7: =+_xlfn.XLOOKUP($A7,MappingTable!$A:$A,MappingTable!E:E) -> Anguilla | G7: =+_xlfn.XLOOKUP($A7,MappingTable!$A:$A,MappingTable!F:F) -> アンギラ | H7: =+_xlfn.XLOOKUP($A7,MappingTable!$A:$A,MappingTable!G:G) -> Anguilla | I7: =+_xlfn.XLOOKUP($A7,MappingTable!$A:$A,MappingTable!H:H) -> Anguila | J7: =+_xlfn.XLOOKUP($A7,MappingTable!$A:$A,MappingTable!I:I) -> Anguilla
A8: AG | B8: Antigua and Barbuda | C8: =+_xlfn.XLOOKUP(A8,MappingTable!A:A,MappingTable!B:B) -> Antigua and Barbuda | D8: =+_xlfn.XLOOKUP($A8,MappingTable!$A:$A,MappingTable!C:C) -> Antigva i Barbuda | E8: =+_xlfn.XLOOKUP($A8,MappingTable!$A:$A,MappingTable!D:D) -> Antigua und Barbuda | F8: =+_xlfn.XLOOKUP($A8,MappingTable!$A:$A,MappingTable!E:E) -> Antigua-et-Barbuda | G8: =+_xlfn.XLOOKUP($A8,MappingTable!$A:$A,MappingTable!F:F) -> アンティグア・バーブーダ | H8: =+_xlfn.XLOOKUP($A8,MappingTable!$A:$A,MappingTable!G:G) -> Antigua e Barbuda | I8: =+_xlfn.XLOOKUP($A8,MappingTable!$A:$A,MappingTable!H:H) -> Antigua y Barbuda | J8: =+_xlfn.XLOOKUP($A8,MappingTable!$A:$A,MappingTable!I:I) -> Antígua e Barbuda
A9: AR | B9: Argentina | C9: =+_xlfn.XLOOKUP(A9,MappingTable!A:A,MappingTable!B:B) -> Argentina | D9: =+_xlfn.XLOOKUP($A9,MappingTable!$A:$A,MappingTable!C:C) -> Argentina | E9: =+_xlfn.XLOOKUP($A9,MappingTable!$A:$A,MappingTable!D:D) -> Argentinien | F9: =+_xlfn.XLOOKUP($A9,MappingTable!$A:$A,MappingTable!E:E) -> Argentine | G9: =+_xlfn.XLOOKUP($A9,MappingTable!$A:$A,MappingTable!F:F) -> アルゼンチン | H9: =+_xlfn.XLOOKUP($A9,MappingTable!$A:$A,MappingTable!G:G) -> Argentina | I9: =+_xlfn.XLOOKUP($A9,MappingTable!$A:$A,MappingTable!H:H) -> Argentina | J9: =+_xlfn.XLOOKUP($A9,MappingTable!$A:$A,MappingTable!I:I) -> Argentina
A10: AM | B10: Armenia | C10: =+_xlfn.XLOOKUP(A10,MappingTable!A:A,MappingTable!B:B) -> Armenia | D10: =+_xlfn.XLOOKUP($A10,MappingTable!$A:$A,MappingTable!C:C) -> Armenija | E10: =+_xlfn.XLOOKUP($A10,MappingTable!$A:$A,MappingTable!D:D) -> Armenien | F10: =+_xlfn.XLOOKUP($A10,MappingTable!$A:$A,MappingTable!E:E) -> Arménie | G10: =+_xlfn.XLOOKUP($A10,MappingTable!$A:$A,MappingTable!F:F) -> アルメニア | H10: =+_xlfn.XLOOKUP($A10,MappingTable!$A:$A,MappingTable!G:G) -> Armenia | I10: =+_xlfn.XLOOKUP($A10,MappingTable!$A:$A,MappingTable!H:H) -> Armenia | J10: =+_xlfn.XLOOKUP($A10,MappingTable!$A:$A,MappingTable!I:I) -> Armênia
A11: AU | B11: Australia | C11: =+_xlfn.XLOOKUP(A11,MappingTable!A:A,MappingTable!B:B) -> Australia | D11: =+_xlfn.XLOOKUP($A11,MappingTable!$A:$A,MappingTable!C:C) -> Australija | E11: =+_xlfn.XLOOKUP($A11,MappingTable!$A:$A,MappingTable!D:D) -> Australien | F11: =+_xlfn.XLOOKUP($A11,MappingTable!$A:$A,MappingTable!E:E) -> Australie | G11: =+_xlfn.XLOOKUP($A11,MappingTable!$A:$A,MappingTable!F:F) -> オーストラリア | H11: =+_xlfn.XLOOKUP($A11,MappingTable!$A:$A,MappingTable!G:G) -> Australia | I11: =+_xlfn.XLOOKUP($A11,MappingTable!$A:$A,MappingTable!H:H) -> Australia | J11: =+_xlfn.XLOOKUP($A11,MappingTable!$A:$A,MappingTable!I:I) -> Austrália
A12: AT | B12: Austria | C12: =+_xlfn.XLOOKUP(A12,MappingTable!A:A,MappingTable!B:B) -> Austria | D12: =+_xlfn.XLOOKUP($A12,MappingTable!$A:$A,MappingTable!C:C) -> Austrija | E12: =+_xlfn.XLOOKUP($A12,MappingTable!$A:$A,MappingTable!D:D) -> Österreich | F12: =+_xlfn.XLOOKUP($A12,MappingTable!$A:$A,MappingTable!E:E) -> Autriche | G12: =+_xlfn.XLOOKUP($A12,MappingTable!$A:$A,MappingTable!F:F) -> オーストリア | H12: =+_xlfn.XLOOKUP($A12,MappingTable!$A:$A,MappingTable!G:G) -> Austria | I12: =+_xlfn.XLOOKUP($A12,MappingTable!$A:$A,MappingTable!H:H) -> Austria | J12: =+_xlfn.XLOOKUP($A12,MappingTable!$A:$A,MappingTable!I:I) -> Áustria
A13: AZ | B13: Azerbaijan | C13: =+_xlfn.XLOOKUP(A13,MappingTable!A:A,MappingTable!B:B) -> Azerbaijan | D13: =+_xlfn.XLOOKUP($A13,MappingTable!$A:$A,MappingTable!C:C) -> Azerbajdžan | E13: =+_xlfn.XLOOKUP($A13,MappingTable!$A:$A,MappingTable!D:D) -> Aserbaidschan | F13: =+_xlfn.XLOOKUP($A13,MappingTable!$A:$A,MappingTable!E:E) -> Azerbaïdjan | G13: =+_xlfn.XLOOKUP($A13,MappingTable!$A:$A,MappingTable!F:F) -> アゼルバイジャン | H13: =+_xlfn.XLOOKUP($A13,MappingTable!$A:$A,MappingTable!G:G) -> Azerbaigian | I13: =+_xlfn.XLOOKUP($A13,MappingTable!$A:$A,MappingTable!H:H) -> Azerbaiyán | J13: =+_xlfn.XLOOKUP($A13,MappingTable!$A:$A,MappingTable!I:I) -> Azerbaijão
A14: BS | B14: Bahamas | C14: =+_xlfn.XLOOKUP(A14,MappingTable!A:A,MappingTable!B:B) -> Bahamas | D14: =+_xlfn.XLOOKUP($A14,MappingTable!$A:$A,MappingTable!C:C) -> Bahami | E14: =+_xlfn.XLOOKUP($A14,MappingTable!$A:$A,MappingTable!D:D) -> Bahamas | F14: =+_xlfn.XLOOKUP($A14,MappingTable!$A:$A,MappingTable!E:E) -> Bahamas | G14: =+_xlfn.XLOOKUP($A14,MappingTable!$A:$A,MappingTable!F:F) -> バハマ | H14: =+_xlfn.XLOOKUP($A14,MappingTable!$A:$A,MappingTable!G:G) -> Bahamas | I14: =+_xlfn.XLOOKUP($A14,MappingTable!$A:$A,MappingTable!H:H) -> Bahamas | J14: =+_xlfn.XLOOKUP($A14,MappingTable!$A:$A,MappingTable!I:I) -> Bahamas
... A30: TC | B30: Turks and Caicos Islands | C30: =+_xlfn.XLOOKUP(A30,MappingTable!A:A,MappingTable!B:B) -> Turks and Caicos Islands | D30: =+_xlfn.XLOOKUP($A30,MappingTable!$A:$A,MappingTable!C:C) -> Otoci Turks i Caicos | E30: =+_xlfn.XLOOKUP($A30,MappingTable!$A:$A,MappingTable!D:D) -> Turks- und Caicosinseln | F30: =+_xlfn.XLOOKUP($A30,MappingTable!$A:$A,MappingTable!E:E) -> Îles Turques-et-Caïques | G30: =+_xlfn.XLOOKUP($A30,MappingTable!$A:$A,MappingTable!F:F) -> タークス・カイコス諸島 | H30: =+_xlfn.XLOOKUP($A30,MappingTable!$A:$A,MappingTable!G:G) -> Isole Turks e Caicos | I30: =+_xlfn.XLOOKUP($A30,MappingTable!$A:$A,MappingTable!H:H) -> Islas Turcas y Caicos | J30: =+_xlfn.XLOOKUP($A30,MappingTable!$A:$A,MappingTable!I:I) -> Ilhas Turks e Caicos
A31: GG | B31: Guernsey | C31: =+_xlfn.XLOOKUP(A31,MappingTable!A:A,MappingTable!B:B) -> Guernsey | D31: =+_xlfn.XLOOKUP(B31,MappingTable!B:B,MappingTable!C:C) -> Guernsey | E31: =+_xlfn.XLOOKUP($A31,MappingTable!$A:$A,MappingTable!D:D) -> Guernsey | F31: =+_xlfn.XLOOKUP($A31,MappingTable!$A:$A,MappingTable!E:E) -> Guernesey | G31: =+_xlfn.XLOOKUP($A31,MappingTable!$A:$A,MappingTable!F:F) -> ガーンジー | H31: =+_xlfn.XLOOKUP($A31,MappingTable!$A:$A,MappingTable!G:G) -> Guernsey | I31: =+_xlfn.XLOOKUP($A31,MappingTable!$A:$A,MappingTable!H:H) -> Guernsey | J31: =+_xlfn.XLOOKUP($A31,MappingTable!$A:$A,MappingTable!I:I) -> Guernsey
A32: JE | B32: Jersey | C32: =+_xlfn.XLOOKUP(A32,MappingTable!A:A,MappingTable!B:B) -> Jersey | D32: =+_xlfn.XLOOKUP(B32,MappingTable!B:B,MappingTable!C:C) -> Jersey | E32: =+_xlfn.XLOOKUP($A32,MappingTable!$A:$A,MappingTable!D:D) -> Jersey | F32: =+_xlfn.XLOOKUP($A32,MappingTable!$A:$A,MappingTable!E:E) -> Jersey | G32: =+_xlfn.XLOOKUP($A32,MappingTable!$A:$A,MappingTable!F:F) -> ジャージー | H32: =+_xlfn.XLOOKUP($A32,MappingTable!$A:$A,MappingTable!G:G) -> Jersey | I32: =+_xlfn.XLOOKUP($A32,MappingTable!$A:$A,MappingTable!H:H) -> Jersey | J32: =+_xlfn.XLOOKUP($A32,MappingTable!$A:$A,MappingTable!I:I) -> Jersey
A33: CL | B33: Chile | C33: =+_xlfn.XLOOKUP(A33,MappingTable!A:A,MappingTable!B:B) -> Chile | D33: =+_xlfn.XLOOKUP($A33,MappingTable!$A:$A,MappingTable!C:C) -> Čile | E33: =+_xlfn.XLOOKUP($A33,MappingTable!$A:$A,MappingTable!D:D) -> Chile | F33: =+_xlfn.XLOOKUP($A33,MappingTable!$A:$A,MappingTable!E:E) -> Chili | G33: =+_xlfn.XLOOKUP($A33,MappingTable!$A:$A,MappingTable!F:F) -> チリ | H33: =+_xlfn.XLOOKUP($A33,MappingTable!$A:$A,MappingTable!G:G) -> Cile | I33: =+_xlfn.XLOOKUP($A33,MappingTable!$A:$A,MappingTable!H:H) -> Chile | J33: =+_xlfn.XLOOKUP($A33,MappingTable!$A:$A,MappingTable!I:I) -> Chile
A34: CN | B34: China | C34: =+_xlfn.XLOOKUP(A34,MappingTable!A:A,MappingTable!B:B) -> China | D34: =+_xlfn.XLOOKUP($A34,MappingTable!$A:$A,MappingTable!C:C) -> Kina | E34: =+_xlfn.XLOOKUP($A34,MappingTable!$A:$A,MappingTable!D:D) -> China | F34: =+_xlfn.XLOOKUP($A34,MappingTable!$A:$A,MappingTable!E:E) -> Chine | G34: =+_xlfn.XLOOKUP($A34,MappingTable!$A:$A,MappingTable!F:F) -> 中華人民共和国 | H34: =+_xlfn.XLOOKUP($A34,MappingTable!$A:$A,MappingTable!G:G) -> Cina | I34: =+_xlfn.XLOOKUP($A34,MappingTable!$A:$A,MappingTable!H:H) -> China | J34: =+_xlfn.XLOOKUP($A34,MappingTable!$A:$A,MappingTable!I:I) -> China
A35: CO | B35: Colombia | C35: =+_xlfn.XLOOKUP(A35,MappingTable!A:A,MappingTable!B:B) -> Colombia | D35: =+_xlfn.XLOOKUP($A35,MappingTable!$A:$A,MappingTable!C:C) -> Kolumbija | E35: =+_xlfn.XLOOKUP($A35,MappingTable!$A:$A,MappingTable!D:D) -> Kolumbien | F35: =+_xlfn.XLOOKUP($A35,MappingTable!$A:$A,MappingTable!E:E) -> Colombie | G35: =+_xlfn.XLOOKUP($A35,MappingTable!$A:$A,MappingTable!F:F) -> コロンビア | H35: =+_xlfn.XLOOKUP($A35,MappingTable!$A:$A,MappingTable!G:G) -> Colombia | I35: =+_xlfn.XLOOKUP($A35,MappingTable!$A:$A,MappingTable!H:H) -> Colombia | J35: =+_xlfn.XLOOKUP($A35,MappingTable!$A:$A,MappingTable!I:I) -> Colômbia
A36: CD | B36: Congo Kinshasa | C36: =+_xlfn.XLOOKUP(A36,MappingTable!A:A,MappingTable!B:B) -> Congo Kinshasa | D36: =+_xlfn.XLOOKUP($A36,MappingTable!$A:$A,MappingTable!C:C) -> Kongo Kinshasa | E36: =+_xlfn.XLOOKUP($A36,MappingTable!$A:$A,MappingTable!D:D) -> Kongo | F36: =+_xlfn.XLOOKUP($A36,MappingTable!$A:$A,MappingTable!E:E) -> République démocratique du Congo | G36: =+_xlfn.XLOOKUP($A36,MappingTable!$A:$A,MappingTable!F:F) -> コンゴ民主共和国 | H36: =+_xlfn.XLOOKUP($A36,MappingTable!$A:$A,MappingTable!G:G) -> Repubblica Democratica del Congo | I36: =+_xlfn.XLOOKUP($A36,MappingTable!$A:$A,MappingTable!H:H) -> Congo (República Democrática del) | J36: =+_xlfn.XLOOKUP($A36,MappingTable!$A:$A,MappingTable!I:I) -> Congo-Kinshasa
A37: CR | B37: Costa Rica | C37: =+_xlfn.XLOOKUP(A37,MappingTable!A:A,MappingTable!B:B) -> Costa Rica | D37: =+_xlfn.XLOOKUP($A37,MappingTable!$A:$A,MappingTable!C:C) -> Kostarika | E37: =+_xlfn.XLOOKUP($A37,MappingTable!$A:$A,MappingTable!D:D) -> Costa Rica | F37: =+_xlfn.XLOOKUP($A37,MappingTable!$A:$A,MappingTable!E:E) -> Costa Rica | G37: =+_xlfn.XLOOKUP($A37,MappingTable!$A:$A,MappingTable!F:F) -> コスタリカ | H37: =+_xlfn.XLOOKUP($A37,MappingTable!$A:$A,MappingTable!G:G) -> Costa Rica | I37: =+_xlfn.XLOOKUP($A37,MappingTable!$A:$A,MappingTable!H:H) -> Costa Rica | J37: =+_xlfn.XLOOKUP($A37,MappingTable!$A:$A,MappingTable!I:I) -> Costa Rica
A38: HR | B38: Croatia | C38: =+_xlfn.XLOOKUP(A38,MappingTable!A:A,MappingTable!B:B) -> Croatia | D38: =+_xlfn.XLOOKUP($A38,MappingTable!$A:$A,MappingTable!C:C) -> Hrvatska | E38: =+_xlfn.XLOOKUP($A38,MappingTable!$A:$A,MappingTable!D:D) -> Kroatien | F38: =+_xlfn.XLOOKUP($A38,MappingTable!$A:$A,MappingTable!E:E) -> Croatie | G38: =+_xlfn.XLOOKUP($A38,MappingTable!$A:$A,MappingTable!F:F) -> クロアチア | H38: =+_xlfn.XLOOKUP($A38,MappingTable!$A:$A,MappingTable!G:G) -> Croazia | I38: =+_xlfn.XLOOKUP($A38,MappingTable!$A:$A,MappingTable!H:H) -> Croacia | J38: =+_xlfn.XLOOKUP($A38,MappingTable!$A:$A,MappingTable!I:I) -> Croácia
A39: CU | B39: Cuba | C39: =+_xlfn.XLOOKUP(A39,MappingTable!A:A,MappingTable!B:B) -> Cuba | D39: =+_xlfn.XLOOKUP($A39,MappingTable!$A:$A,MappingTable!C:C) -> Kuba | E39: =+_xlfn.XLOOKUP($A39,MappingTable!$A:$A,MappingTable!D:D) -> Kuba | F39: =+_xlfn.XLOOKUP($A39,MappingTable!$A:$A,MappingTable!E:E) -> Cuba | G39: =+_xlfn.XLOOKUP($A39,MappingTable!$A:$A,MappingTable!F:F) -> キューバ | H39: =+_xlfn.XLOOKUP($A39,MappingTable!$A:$A,MappingTable!G:G) -> Cuba | I39: =+_xlfn.XLOOKUP($A39,MappingTable!$A:$A,MappingTable!H:H) -> Cuba | J39: =+_xlfn.XLOOKUP($A39,MappingTable!$A:$A,MappingTable!I:I) -> Cuba
A40: CY | B40: Cyprus | C40: =+_xlfn.XLOOKUP(A40,MappingTable!A:A,MappingTable!B:B) -> Cyprus | D40: =+_xlfn.XLOOKUP($A40,MappingTable!$A:$A,MappingTable!C:C) -> Cipar | E40: =+_xlfn.XLOOKUP($A40,MappingTable!$A:$A,MappingTable!D:D) -> Zypern | F40: =+_xlfn.XLOOKUP($A40,MappingTable!$A:$A,MappingTable!E:E) -> Chypre | G40: =+_xlfn.XLOOKUP($A40,MappingTable!$A:$A,MappingTable!F:F) -> キプロス | H40: =+_xlfn.XLOOKUP($A40,MappingTable!$A:$A,MappingTable!G:G) -> Cipro | I40: =+_xlfn.XLOOKUP($A40,MappingTable!$A:$A,MappingTable!H:H) -> Chipre | J40: =+_xlfn.XLOOKUP($A40,MappingTable!$A:$A,MappingTable!I:I) -> Chipre
A41: CZ | B41: Czech Republic | C41: =+_xlfn.XLOOKUP(A41,MappingTable!A:A,MappingTable!B:B) -> Czech Republic | D41: =+_xlfn.XLOOKUP($A41,MappingTable!$A:$A,MappingTable!C:C) -> Češka | E41: =+_xlfn.XLOOKUP($A41,MappingTable!$A:$A,MappingTable!D:D) -> Tschechische Republik | F41: =+_xlfn.XLOOKUP($A41,MappingTable!$A:$A,MappingTable!E:E) -> République Tchèque | G41: =+_xlfn.XLOOKUP($A41,MappingTable!$A:$A,MappingTable!F:F) -> チェコ | H41: =+_xlfn.XLOOKUP($A41,MappingTable!$A:$A,MappingTable!G:G) -> Repubblica Ceca | I41: =+_xlfn.XLOOKUP($A41,MappingTable!$A:$A,MappingTable!H:H) -> República Checa | J41: =+_xlfn.XLOOKUP($A41,MappingTable!$A:$A,MappingTable!I:I) -> Chéquia | K41: Czechia
A42: DK | B42: Denmark | C42: =+_xlfn.XLOOKUP(A42,MappingTable!A:A,MappingTable!B:B) -> Denmark | D42: =+_xlfn.XLOOKUP($A42,MappingTable!$A:$A,MappingTable!C:C) -> Danska | E42: =+_xlfn.XLOOKUP($A42,MappingTable!$A:$A,MappingTable!D:D) -> Dänemark | F42: =+_xlfn.XLOOKUP($A42,MappingTable!$A:$A,MappingTable!E:E) -> Danemark | G42: =+_xlfn.XLOOKUP($A42,MappingTable!$A:$A,MappingTable!F:F) -> デンマーク | H42: =+_xlfn.XLOOKUP($A42,MappingTable!$A:$A,MappingTable!G:G) -> Danimarca | I42: =+_xlfn.XLOOKUP($A42,MappingTable!$A:$A,MappingTable!H:H) -> Dinamarca | J42: =+_xlfn.XLOOKUP($A42,MappingTable!$A:$A,MappingTable!I:I) -> Dinamarca
A43: EC | B43: Ecuador | C43: =+_xlfn.XLOOKUP(A43,MappingTable!A:A,MappingTable!B:B) -> Ecuador | D43: =+_xlfn.XLOOKUP($A43,MappingTable!$A:$A,MappingTable!C:C) -> Ekvador | E43: =+_xlfn.XLOOKUP($A43,MappingTable!$A:$A,MappingTable!D:D) -> Ecuador | F43: =+_xlfn.XLOOKUP($A43,MappingTable!$A:$A,MappingTable!E:E) -> Équateur | G43: =+_xlfn.XLOOKUP($A43,MappingTable!$A:$A,MappingTable!F:F) -> エクアドル | H43: =+_xlfn.XLOOKUP($A43,MappingTable!$A:$A,MappingTable!G:G) -> Ecuador | I43: =+_xlfn.XLOOKUP($A43,MappingTable!$A:$A,MappingTable!H:H) -> Ecuador | J43: =+_xlfn.XLOOKUP($A43,MappingTable!$A:$A,MappingTable!I:I) -> Equador
A44: EG | B44: Egypt | C44: =+_xlfn.XLOOKUP(A44,MappingTable!A:A,MappingTable!B:B) -> Egypt | D44: =+_xlfn.XLOOKUP($A44,MappingTable!$A:$A,MappingTable!C:C) -> Egipat | E44: =+_xlfn.XLOOKUP($A44,MappingTable!$A:$A,MappingTable!D:D) -> Ägypten | F44: =+_xlfn.XLOOKUP($A44,MappingTable!$A:$A,MappingTable!E:E) -> Égypte | G44: =+_xlfn.XLOOKUP($A44,MappingTable!$A:$A,MappingTable!F:F) -> エジプト | H44: =+_xlfn.XLOOKUP($A44,MappingTable!$A:$A,MappingTable!G:G) -> Egitto | I44: =+_xlfn.XLOOKUP($A44,MappingTable!$A:$A,MappingTable!H:H) -> Egipto | J44: =+_xlfn.XLOOKUP($A44,MappingTable!$A:$A,MappingTable!I:I) -> Egito
A45: SR | B45: Suriname | C45: =+_xlfn.XLOOKUP(A45,MappingTable!A:A,MappingTable!B:B) -> Suriname | D45: =+_xlfn.XLOOKUP($A45,MappingTable!$A:$A,MappingTable!C:C) -> Surinam | E45: =+_xlfn.XLOOKUP($A45,MappingTable!$A:$A,MappingTable!D:D) -> Suriname | F45: =+_xlfn.XLOOKUP($A45,MappingTable!$A:$A,MappingTable!E:E) -> Suriname | G45: =+_xlfn.XLOOKUP($A45,MappingTable!$A:$A,MappingTable!F:F) -> スリナム | H45: =+_xlfn.XLOOKUP($A45,MappingTable!$A:$A,MappingTable!G:G) -> Suriname | I45: =+_xlfn.XLOOKUP($A45,MappingTable!$A:$A,MappingTable!H:H) -> Surinam | J45: =+_xlfn.XLOOKUP($A45,MappingTable!$A:$A,MappingTable!I:I) -> Suriname
A46: EE | B46: Estonia | C46: =+_xlfn.XLOOKUP(A46,MappingTable!A:A,MappingTable!B:B) -> Estonia | D46: =+_xlfn.XLOOKUP($A46,MappingTable!$A:$A,MappingTable!C:C) -> Estonija | E46: =+_xlfn.XLOOKUP($A46,MappingTable!$A:$A,MappingTable!D:D) -> Estland | F46: =+_xlfn.XLOOKUP($A46,MappingTable!$A:$A,MappingTable!E:E) -> Estonie | G46: =+_xlfn.XLOOKUP($A46,MappingTable!$A:$A,MappingTable!F:F) -> エストニア | H46: =+_xlfn.XLOOKUP($A46,MappingTable!$A:$A,MappingTable!G:G) -> Estonia | I46: =+_xlfn.XLOOKUP($A46,MappingTable!$A:$A,MappingTable!H:H) -> Estonia | J46: =+_xlfn.XLOOKUP($A46,MappingTable!$A:$A,MappingTable!I:I) -> Estônia
A47: ET | B47: Ethiopia | C47: =+_xlfn.XLOOKUP(A47,MappingTable!A:A,MappingTable!B:B) -> Ethiopia | D47: =+_xlfn.XLOOKUP($A47,MappingTable!$A:$A,MappingTable!C:C) -> Etiopija | E47: =+_xlfn.XLOOKUP($A47,MappingTable!$A:$A,MappingTable!D:D) -> Äthiopien | F47: =+_xlfn.XLOOKUP($A47,MappingTable!$A:$A,MappingTable!E:E) -> Éthiopie | G47: =+_xlfn.XLOOKUP($A47,MappingTable!$A:$A,MappingTable!F:F) -> エチオピア | H47: =+_xlfn.XLOOKUP($A47,MappingTable!$A:$A,MappingTable!G:G) -> Etiopia | I47: =+_xlfn.XLOOKUP($A47,MappingTable!$A:$A,MappingTable!H:H) -> Etiopía | J47: =+_xlfn.XLOOKUP($A47,MappingTable!$A:$A,MappingTable!I:I) -> Etiópia
A48: FO | B48: Faroe Islands | C48: =+_xlfn.XLOOKUP(A48,MappingTable!A:A,MappingTable!B:B) -> Faroe Islands | D48: =+_xlfn.XLOOKUP($A48,MappingTable!$A:$A,MappingTable!C:C) -> Farski otoci | E48: =+_xlfn.XLOOKUP($A48,MappingTable!$A:$A,MappingTable!D:D) -> Färöer | F48: =+_xlfn.XLOOKUP($A48,MappingTable!$A:$A,MappingTable!E:E) -> Îles Féroé | G48: =+_xlfn.XLOOKUP($A48,MappingTable!$A:$A,MappingTable!F:F) -> フェロー諸島 | H48: =+_xlfn.XLOOKUP($A48,MappingTable!$A:$A,MappingTable!G:G) -> Isole Fær Øer | I48: =+_xlfn.XLOOKUP($A48,MappingTable!$A:$A,MappingTable!H:H) -> Islas Feroe | J48: =+_xlfn.XLOOKUP($A48,MappingTable!$A:$A,MappingTable!I:I) -> Ilhas Faroé
A49: FJ | B49: Fiji | C49: =+_xlfn.XLOOKUP(A49,MappingTable!A:A,MappingTable!B:B) -> Fiji | D49: =+_xlfn.XLOOKUP($A49,MappingTable!$A:$A,MappingTable!C:C) -> Fidži | E49: =+_xlfn.XLOOKUP($A49,MappingTable!$A:$A,MappingTable!D:D) -> Fidschi | F49: =+_xlfn.XLOOKUP($A49,MappingTable!$A:$A,MappingTable!E:E) -> Fidji | G49: =+_xlfn.XLOOKUP($A49,MappingTable!$A:$A,MappingTable!F:F) -> フィジー | H49: =+_xlfn.XLOOKUP($A49,MappingTable!$A:$A,MappingTable!G:G) -> Figi | I49: =+_xlfn.XLOOKUP($A49,MappingTable!$A:$A,MappingTable!H:H) -> Fiji | J49: =+_xlfn.XLOOKUP($A49,MappingTable!$A:$A,MappingTable!I:I) -> Fiji
A50: FI | B50: Finland | C50: =+_xlfn.XLOOKUP(A50,MappingTable!A:A,MappingTable!B:B) -> Finland | D50: =+_xlfn.XLOOKUP($A50,MappingTable!$A:$A,MappingTable!C:C) -> Finska | E50: =+_xlfn.XLOOKUP($A50,MappingTable!$A:$A,MappingTable!D:D) -> Finnland | F50: =+_xlfn.XLOOKUP($A50,MappingTable!$A:$A,MappingTable!E:E) -> Finlande | G50: =+_xlfn.XLOOKUP($A50,MappingTable!$A:$A,MappingTable!F:F) -> フィンランド | H50: =+_xlfn.XLOOKUP($A50,MappingTable!$A:$A,MappingTable!G:G) -> Finlandia | I50: =+_xlfn.XLOOKUP($A50,MappingTable!$A:$A,MappingTable!H:H) -> Finlandia | J50: =+_xlfn.XLOOKUP($A50,MappingTable!$A:$A,MappingTable!I:I) -> Finlândia
A51: FR | B51: France | C51: =+_xlfn.XLOOKUP(A51,MappingTable!A:A,MappingTable!B:B) -> France | D51: =+_xlfn.XLOOKUP($A51,MappingTable!$A:$A,MappingTable!C:C) -> Francuska | E51: =+_xlfn.XLOOKUP($A51,MappingTable!$A:$A,MappingTable!D:D) -> Frankreich | F51: =+_xlfn.XLOOKUP($A51,MappingTable!$A:$A,MappingTable!E:E) -> France | G51: =+_xlfn.XLOOKUP($A51,MappingTable!$A:$A,MappingTable!F:F) -> フランス | H51: =+_xlfn.XLOOKUP($A51,MappingTable!$A:$A,MappingTable!G:G) -> Francia | I51: =+_xlfn.XLOOKUP($A51,MappingTable!$A:$A,MappingTable!H:H) -> Francia | J51: =+_xlfn.XLOOKUP($A51,MappingTable!$A:$A,MappingTable!I:I) -> França
A52: PF | B52: French Polynesia | C52: =+_xlfn.XLOOKUP(A52,MappingTable!A:A,MappingTable!B:B) -> French Polynesia | D52: =+_xlfn.XLOOKUP($A52,MappingTable!$A:$A,MappingTable!C:C) -> Francuska Polinezija | E52: =+_xlfn.XLOOKUP($A52,MappingTable!$A:$A,MappingTable!D:D) -> Französisch-Polynesien | F52: =+_xlfn.XLOOKUP($A52,MappingTable!$A:$A,MappingTable!E:E) -> Polynésie française | G52: =+_xlfn.XLOOKUP($A52,MappingTable!$A:$A,MappingTable!F:F) -> フランス領ポリネシア | H52: =+_xlfn.XLOOKUP($A52,MappingTable!$A:$A,MappingTable!G:G) -> Polinesia Francese | I52: =+_xlfn.XLOOKUP($A52,MappingTable!$A:$A,MappingTable!H:H) -> Polinesia Francesa | J52: =+_xlfn.XLOOKUP($A52,MappingTable!$A:$A,MappingTable!I:I) -> Polinésia Francesa
A53: GP | B53: Guadeloupe | C53: =+_xlfn.XLOOKUP(A53,MappingTable!A:A,MappingTable!B:B) -> Guadeloupe | D53: =+_xlfn.XLOOKUP($A53,MappingTable!$A:$A,MappingTable!C:C) -> Guadalupe | E53: =+_xlfn.XLOOKUP($A53,MappingTable!$A:$A,MappingTable!D:D) -> Guadeloupe | F53: =+_xlfn.XLOOKUP($A53,MappingTable!$A:$A,MappingTable!E:E) -> Guadeloupe | G53: =+_xlfn.XLOOKUP($A53,MappingTable!$A:$A,MappingTable!F:F) -> グアドループ | H53: =+_xlfn.XLOOKUP($A53,MappingTable!$A:$A,MappingTable!G:G) -> Guadalupa | I53: =+_xlfn.XLOOKUP($A53,MappingTable!$A:$A,MappingTable!H:H) -> Guadalupe | J53: =+_xlfn.XLOOKUP($A53,MappingTable!$A:$A,MappingTable!I:I) -> Guadalupe
... A128: SG | B128: Singapore | C128: =+_xlfn.XLOOKUP(A128,MappingTable!A:A,MappingTable!B:B) -> Singapore | D128: =+_xlfn.XLOOKUP($A128,MappingTable!$A:$A,MappingTable!C:C) -> Singapur | E128: =+_xlfn.XLOOKUP($A128,MappingTable!$A:$A,MappingTable!D:D) -> Singapur | F128: =+_xlfn.XLOOKUP($A128,MappingTable!$A:$A,MappingTable!E:E) -> Singapour | G128: =+_xlfn.XLOOKUP($A128,MappingTable!$A:$A,MappingTable!F:F) -> シンガポール | H128: =+_xlfn.XLOOKUP($A128,MappingTable!$A:$A,MappingTable!G:G) -> Singapore | I128: =+_xlfn.XLOOKUP($A128,MappingTable!$A:$A,MappingTable!H:H) -> Singapur | J128: =+_xlfn.XLOOKUP($A128,MappingTable!$A:$A,MappingTable!I:I) -> Singapura
A129: SK | B129: Slovakia | C129: =+_xlfn.XLOOKUP(A129,MappingTable!A:A,MappingTable!B:B) -> Slovakia | D129: =+_xlfn.XLOOKUP($A129,MappingTable!$A:$A,MappingTable!C:C) -> Slovačka | E129: =+_xlfn.XLOOKUP($A129,MappingTable!$A:$A,MappingTable!D:D) -> Slowakei | F129: =+_xlfn.XLOOKUP($A129,MappingTable!$A:$A,MappingTable!E:E) -> Slovaquie | G129: =+_xlfn.XLOOKUP($A129,MappingTable!$A:$A,MappingTable!F:F) -> スロバキア | H129: =+_xlfn.XLOOKUP($A129,MappingTable!$A:$A,MappingTable!G:G) -> Slovacchia | I129: =+_xlfn.XLOOKUP($A129,MappingTable!$A:$A,MappingTable!H:H) -> Eslovaquia | J129: =+_xlfn.XLOOKUP($A129,MappingTable!$A:$A,MappingTable!I:I) -> Eslováquia | K129: Slovak Republic
...

Sheet Countries_per_regions
A1: No | B1: Region_Code | C1: Region product name | D1: Countries_ISO2 | E1: Countries | F1: Country_Count
A2: 1 | B2: =OFFSET(Regions!D1,A2,0) -> GLBL | C2: =OFFSET(Regions!D1,A2,1) -> Global | D2: {=TRANSPOSE(TRIM(_xlfn.TEXTSPLIT(OFFSET(Regions!G1,A2,0),",")))} -> AD | E2: =+IF(ISBLANK(D2),"",_xlfn.XLOOKUP(D2,Countries!A:A,Countries!B:B,"")) -> Andorra | F2: =OFFSET(Regions!D1,A2,2) -> 188
A3: =+IF(ISBLANK(D3),"",A2) -> 1 | B3: =+IF(ISBLANK(D3),"",B2) -> GLBL | C3: =+IF(ISBLANK(D3),"",C2) -> Global | D3: AE | E3: =+IF(ISBLANK(D3),"",_xlfn.XLOOKUP(D3,Countries!A:A,Countries!B:B,"")) -> United Arab Emirates | F3: {=+IF(ISBLANK(D¸¸3),"",F2)} -> 188
A4: =+IF(ISBLANK(D4),"",A3) -> 1 | B4: =+IF(ISBLANK(D4),"",B3) -> GLBL | C4: =+IF(ISBLANK(D4),"",C3) -> Global | D4: AF | E4: =+IF(ISBLANK(D4),"",_xlfn.XLOOKUP(D4,Countries!A:A,Countries!B:B,"")) -> Afghanistan | F4: =+IF(ISBLANK(D4),"",F3) -> 188
A5: =+IF(ISBLANK(D5),"",A4) -> 1 | B5: =+IF(ISBLANK(D5),"",B4) -> GLBL | C5: =+IF(ISBLANK(D5),"",C4) -> Global | D5: AG | E5: =+IF(ISBLANK(D5),"",_xlfn.XLOOKUP(D5,Countries!A:A,Countries!B:B,"")) -> Antigua and Barbuda | F5: =+IF(ISBLANK(D5),"",F4) -> 188
A6: =+IF(ISBLANK(D6),"",A5) -> 1 | B6: =+IF(ISBLANK(D6),"",B5) -> GLBL | C6: =+IF(ISBLANK(D6),"",C5) -> Global | D6: AI | E6: =+IF(ISBLANK(D6),"",_xlfn.XLOOKUP(D6,Countries!A:A,Countries!B:B,"")) -> Anguilla | F6: =+IF(ISBLANK(D6),"",F5) -> 188
A7: =+IF(ISBLANK(D7),"",A6) -> 1 | B7: =+IF(ISBLANK(D7),"",B6) -> GLBL | C7: =+IF(ISBLANK(D7),"",C6) -> Global | D7: AL | E7: =+IF(ISBLANK(D7),"",_xlfn.XLOOKUP(D7,Countries!A:A,Countries!B:B,"")) -> Albania | F7: =+IF(ISBLANK(D7),"",F6) -> 188
A8: =+IF(ISBLANK(D8),"",A7) -> 1 | B8: =+IF(ISBLANK(D8),"",B7) -> GLBL | C8: =+IF(ISBLANK(D8),"",C7) -> Global | D8: AM | E8: =+IF(ISBLANK(D8),"",_xlfn.XLOOKUP(D8,Countries!A:A,Countries!B:B,"")) -> Armenia | F8: =+IF(ISBLANK(D8),"",F7) -> 188
A9: =+IF(ISBLANK(D9),"",A8) -> 1 | B9: =+IF(ISBLANK(D9),"",B8) -> GLBL | C9: =+IF(ISBLANK(D9),"",C8) -> Global | D9: AO | E9: =+IF(ISBLANK(D9),"",_xlfn.XLOOKUP(D9,Countries!A:A,Countries!B:B,"")) -> Angola | F9: =+IF(ISBLANK(D9),"",F8) -> 188
A10: =+IF(ISBLANK(D10),"",A9) -> 1 | B10: =+IF(ISBLANK(D10),"",B9) -> GLBL | C10: =+IF(ISBLANK(D10),"",C9) -> Global | D10: AR | E10: =+IF(ISBLANK(D10),"",_xlfn.XLOOKUP(D10,Countries!A:A,Countries!B:B,"")) -> Argentina | F10: =+IF(ISBLANK(D10),"",F9) -> 188
A11: =+IF(ISBLANK(D11),"",A10) -> 1 | B11: =+IF(ISBLANK(D11),"",B10) -> GLBL | C11: =+IF(ISBLANK(D11),"",C10) -> Global | D11: AT | E11: =+IF(ISBLANK(D11),"",_xlfn.XLOOKUP(D11,Countries!A:A,Countries!B:B,"")) -> Austria | F11: =+IF(ISBLANK(D11),"",F10) -> 188
A12: =+IF(ISBLANK(D12),"",A11) -> 1 | B12: =+IF(ISBLANK(D12),"",B11) -> GLBL | C12: =+IF(ISBLANK(D12),"",C11) -> Global | D12: AU | E12: =+IF(ISBLANK(D12),"",_xlfn.XLOOKUP(D12,Countries!A:A,Countries!B:B,"")) -> Australia | F12: =+IF(ISBLANK(D12),"",F11) -> 188
A13: =+IF(ISBLANK(D13),"",A12) -> 1 | B13: =+IF(ISBLANK(D13),"",B12) -> GLBL | C13: =+IF(ISBLANK(D13),"",C12) -> Global | D13: AZ | E13: =+IF(ISBLANK(D13),"",_xlfn.XLOOKUP(D13,Countries!A:A,Countries!B:B,"")) -> Azerbaijan | F13: =+IF(ISBLANK(D13),"",F12) -> 188
A14: =+IF(ISBLANK(D14),"",A13) -> 1 | B14: =+IF(ISBLANK(D14),"",B13) -> GLBL | C14: =+IF(ISBLANK(D14),"",C13) -> Global | D14: BA | E14: =+IF(ISBLANK(D14),"",_xlfn.XLOOKUP(D14,Countries!A:A,Countries!B:B,"")) -> Bosnia and Herzegovina | F14: =+IF(ISBLANK(D14),"",F13) -> 188
A15: =+IF(ISBLANK(D15),"",A14) -> 1 | B15: =+IF(ISBLANK(D15),"",B14) -> GLBL | C15: =+IF(ISBLANK(D15),"",C14) -> Global | D15: BB | E15: =+IF(ISBLANK(D15),"",_xlfn.XLOOKUP(D15,Countries!A:A,Countries!B:B,"")) -> Barbados | F15: =+IF(ISBLANK(D15),"",F14) -> 188
... A189: =+IF(ISBLANK(D189),"",A188) -> 1 | B189: =+IF(ISBLANK(D189),"",B188) -> GLBL | C189: =+IF(ISBLANK(D189),"",C188) -> Global | D189: ZW | E189: =+IF(ISBLANK(D189),"",_xlfn.XLOOKUP(D189,Countries!A:A,Countries!B:B,"")) -> Zimbabwe | F189: =+IF(ISBLANK(D189),"",F188) -> 188

Sheet MappingTable
A1: ISO_2 | B1: en | C1: hr | D1: de | E1: fr | F1: ja | G1: it | H1: es | I1: pt
A2: AD | B2: Andorra | C2: Andora | D2: Andorra | E2: Andorre | F2: アンドラ | G2: Andorra | H2: Andorra | I2: Andorra
A3: AE | B3: United Arab Emirates | C3: Ujedinjeni Arapski Emirati | D3: Vereinigte Arabische Emirate | E3: Émirats Arabes Unis | F3: アラブ首長国連邦 | G3: Emirati Arabi Uniti | H3: Emiratos Árabes Unidos | I3: Emirados Árabes Unidos
A4: AF | B4: Afghanistan | C4: Afganistan | D4: Afghanistan | E4: Afghanistan | F4: アフガニスタン | G4: Afghanistan | H4: Afganistán | I4: Afeganistão
A5: AG | B5: Antigua and Barbuda | C5: Antigva i Barbuda | D5: Antigua und Barbuda | E5: Antigua-et-Barbuda | F5: アンティグア・バーブーダ | G5: Antigua e Barbuda | H5: Antigua y Barbuda | I5: Antígua e Barbuda
A6: AI | B6: Anguilla | C6: Angvila | D6: Anguilla | E6: Anguilla | F6: アンギラ | G6: Anguilla | H6: Anguila | I6: Anguilla
A7: AL | B7: Albania | C7: Albanija | D7: Albanien | E7: Albanie | F7: アルバニア | G7: Albania | H7: Albania | I7: Albânia
A8: AM | B8: Armenia | C8: Armenija | D8: Armenien | E8: Arménie | F8: アルメニア | G8: Armenia | H8: Armenia | I8: Armênia
A9: AO | B9: Angola | C9: Angola | D9: Angola | E9: Angola | F9: アンゴラ | G9: Angola | H9: Angola | I9: Angola
A10: AR | B10: Argentina | C10: Argentina | D10: Argentinien | E10: Argentine | F10: アルゼンチン | G10: Argentina | H10: Argentina | I10: Argentina
A11: AT | B11: Austria | C11: Austrija | D11: Österreich | E11: Autriche | F11: オーストリア | G11: Austria | H11: Austria | I11: Áustria
A12: AU | B12: Australia | C12: Australija | D12: Australien | E12: Australie | F12: オーストラリア | G12: Australia | H12: Australia | I12: Austrália
... A78: IL | B78: Israel | C78: Izrael | D78: Israel | E78: Israël | F78: イスラエル | G78: Israele | H78: Israel | I78: Israel
A79: IM | B79: Isle of Man | C79: Otok Man | D79: Insel Man | E79: Île de Man | F79: マン島 | G79: Isola di Man | H79: Isla de Man | I79: #N/A
A80: IN | B80: India | C80: Indija | D80: Indien | E80: Inde | F80: インド | G80: India | H80: India | I80: Índia
A81: IQ | B81: Iraq | C81: Irak | D81: Irak | E81: Irak | F81: イラク | G81: Iraq | H81: Iraq | I81: Iraque
A82: IR | B82: Iran | C82: Iran | D82: Iran | E82: Iran | F82: イラン・イスラム共和国 | G82: Iran | H82: Irán | I82: Irã
A83: IS | B83: Iceland | C83: Island | D83: Island | E83: Islande | F83: アイスランド | G83: Islanda | H83: Islandia | I83: Islândia
A84: IT | B84: Italy | C84: Italija | D84: Italien | E84: Italie | F84: イタリア | G84: Italia | H84: Italia | I84: Itália
A85: JE | B85: Jersey | C85: Jersey | D85: Jersey | E85: Jersey | F85: ジャージー | G85: Jersey | H85: Jersey | I85: Jersey
A86: JM | B86: Jamaica | C86: Jamajka | D86: Jamaika | E86: Jamaïque | F86: ジャマイカ | G86: Giamaica | H86: Jamaica | I86: Jamaica
A87: JO | B87: Jordan | C87: Jordan | D87: Jordanien | E87: Jordanie | F87: ヨルダン | G87: Giordania | H87: Jordania | I87: Jordânia
A88: JP | B88: Japan | C88: Japan | D88: Japan | E88: Japon | F88: 日本 | G88: Giappone | H88: Japón | I88: Japão
A89: KE | B89: Kenya | C89: Kenija | D89: Kenia | E89: Kenya | F89: ケニア | G89: Kenya | H89: Kenia | I89: Quênia
A90: KG | B90: Kyrgyzstan | C90: Kirgistan | D90: Kirgisistan | E90: Kirghizistan | F90: キルギス | G90: Kirghizistan | H90: Kirguistán | I90: Quirguistão
A91: KH | B91: Cambodia | C91: Kambodža | D91: Kambodscha | E91: Cambodge | F91: カンボジア | G91: Cambogia | H91: Camboya | I91: Camboja
... A190: MW | B190: Malawi | C190: Malavi | D190: Malawi | E190: Malawi | F190: マラウイ | G190: Malawi | H190: Malaui | I190: Malaui
