Workbook

Sheet Crodis
A1: country | B1: operator | C1: dIOT PSD | D1: dIOT (GB) | E1: Min | F1: ISO_Code_A3 | G1: ISO_Code_A2 | H1: ISO_Code_Numeric
A2: Aerospace | B2: AeroMobile (AAA) | C2: 0.2068402 | D2: =C2*1024 -> 211.80437 | E2: =_xlfn.MINIFS(D:D,A:A,A2,D:D,"<>0") -> 211.80437 | F2: =_xlfn.TEXTBEFORE(_xlfn.TEXTAFTER(B2,"("),")") -> AAA | G2: =+_xlfn.XLOOKUP(F2,Sheet1!C:C,Sheet1!B:B,"N/A",0) -> N/A | H2: =+_xlfn.XLOOKUP(F2,Sheet1!C:C,Sheet1!D:D,"N/A",0) -> N/A
A3: Aerospace | B3: Thuraya (AAZ) | D3: =C3*1024 -> 0 | E3: =_xlfn.MINIFS(D:D,A:A,A3,D:D,"<>0") -> 211.80437 | F3: =_xlfn.TEXTBEFORE(_xlfn.TEXTAFTER(B3,"("),")") -> AAZ | G3: =+_xlfn.XLOOKUP(F3,Sheet1!C:C,Sheet1!B:B,"N/A",0) -> N/A | H3: =+_xlfn.XLOOKUP(F3,Sheet1!C:C,Sheet1!D:D,"N/A",0) -> N/A
A4: Afghanistan | B4: Afghan Wireless (AFG) | C4: 0.0033939 | D4: =C4*1024 -> 3.4753536 | E4: =_xlfn.MINIFS(D:D,A:A,A4,D:D,"<>0") -> 2.1786624 | F4: =_xlfn.TEXTBEFORE(_xlfn.TEXTAFTER(B4,"("),")") -> AFG | G4: =+_xlfn.XLOOKUP(F4,Sheet1!C:C,Sheet1!B:B,"N/A",0) -> AF | H4: =+_xlfn.XLOOKUP(F4,Sheet1!C:C,Sheet1!D:D,"N/A",0) -> 004
A5: Afghanistan | B5: Atoma (AFG) | C5: 0.005 | D5: =C5*1024 -> 5.12 | E5: =_xlfn.MINIFS(D:D,A:A,A5,D:D,"<>0") -> 2.1786624 | F5: =_xlfn.TEXTBEFORE(_xlfn.TEXTAFTER(B5,"("),")") -> AFG | G5: =+_xlfn.XLOOKUP(F5,Sheet1!C:C,Sheet1!B:B,"N/A",0) -> AF | H5: =+_xlfn.XLOOKUP(F5,Sheet1!C:C,Sheet1!D:D,"N/A",0) -> 004
A6: Afghanistan | B6: Etisalat (AFG) | C6: 0.004142 | D6: =C6*1024 -> 4.241408 | E6: =_xlfn.MINIFS(D:D,A:A,A6,D:D,"<>0") -> 2.1786624 | F6: =_xlfn.TEXTBEFORE(_xlfn.TEXTAFTER(B6,"("),")") -> AFG | G6: =+_xlfn.XLOOKUP(F6,Sheet1!C:C,Sheet1!B:B,"N/A",0) -> AF | H6: =+_xlfn.XLOOKUP(F6,Sheet1!C:C,Sheet1!D:D,"N/A",0) -> 004
A7: Afghanistan | B7: Roshan (AFG) | C7: 0.0021276 | D7: =C7*1024 -> 2.1786624 | E7: =_xlfn.MINIFS(D:D,A:A,A7,D:D,"<>0") -> 2.1786624 | F7: =_xlfn.TEXTBEFORE(_xlfn.TEXTAFTER(B7,"("),")") -> AFG | G7: =+_xlfn.XLOOKUP(F7,Sheet1!C:C,Sheet1!B:B,"N/A",0) -> AF | H7: =+_xlfn.XLOOKUP(F7,Sheet1!C:C,Sheet1!D:D,"N/A",0) -> 004
A8: Albania | B8: One Albania (ALB) | C8: 0.0008074 | D8: =C8*1024 -> 0.8267776 | E8: =_xlfn.MINIFS(D:D,A:A,A8,D:D,"<>0") -> 0.82005932 | F8: =_xlfn.TEXTBEFORE(_xlfn.TEXTAFTER(B8,"("),")") -> ALB | G8: =+_xlfn.XLOOKUP(F8,Sheet1!C:C,Sheet1!B:B,"N/A",0) -> AL | H8: =+_xlfn.XLOOKUP(F8,Sheet1!C:C,Sheet1!D:D,"N/A",0) -> 008
A9: Albania | B9: Vodafone (ALB) | C9: 0.00080083918 | D9: =C9*1024 -> 0.82005932 | E9: =_xlfn.MINIFS(D:D,A:A,A9,D:D,"<>0") -> 0.82005932 | F9: =_xlfn.TEXTBEFORE(_xlfn.TEXTAFTER(B9,"("),")") -> ALB | G9: =+_xlfn.XLOOKUP(F9,Sheet1!C:C,Sheet1!B:B,"N/A",0) -> AL | H9: =+_xlfn.XLOOKUP(F9,Sheet1!C:C,Sheet1!D:D,"N/A",0) -> 008
A10: Algeria | B10: ATM (DZA) | C10: 0.001 | D10: =C10*1024 -> 1.024 | E10: =_xlfn.MINIFS(D:D,A:A,A10,D:D,"<>0") -> 1.024 | F10: =_xlfn.TEXTBEFORE(_xlfn.TEXTAFTER(B10,"("),")") -> DZA | G10: =+_xlfn.XLOOKUP(F10,Sheet1!C:C,Sheet1!B:B,"N/A",0) -> DZ | H10: =+_xlfn.XLOOKUP(F10,Sheet1!C:C,Sheet1!D:D,"N/A",0) -> 012
A11: Algeria | B11: Ooredoo (DZA) | C11: 0.002156 | D11: =C11*1024 -> 2.207744 | E11: =_xlfn.MINIFS(D:D,A:A,A11,D:D,"<>0") -> 1.024 | F11: =_xlfn.TEXTBEFORE(_xlfn.TEXTAFTER(B11,"("),")") -> DZA | G11: =+_xlfn.XLOOKUP(F11,Sheet1!C:C,Sheet1!B:B,"N/A",0) -> DZ | H11: =+_xlfn.XLOOKUP(F11,Sheet1!C:C,Sheet1!D:D,"N/A",0) -> 012
A12: Algeria | B12: Veon (DZA) | C12: 0.010300242 | D12: =C12*1024 -> 10.547448 | E12: =_xlfn.MINIFS(D:D,A:A,A12,D:D,"<>0") -> 1.024 | F12: =_xlfn.TEXTBEFORE(_xlfn.TEXTAFTER(B12,"("),")") -> DZA | G12: =+_xlfn.XLOOKUP(F12,Sheet1!C:C,Sheet1!B:B,"N/A",0) -> DZ | H12: =+_xlfn.XLOOKUP(F12,Sheet1!C:C,Sheet1!D:D,"N/A",0) -> 012
A13: American Samoa | B13: Bluesky (ASM) | C13: 0.3889004 | D13: =C13*1024 -> 398.23401 | E13: =_xlfn.MINIFS(D:D,A:A,A13,D:D,"<>0") -> 398.23401 | F13: =_xlfn.TEXTBEFORE(_xlfn.TEXTAFTER(B13,"("),")") -> ASM | G13: =+_xlfn.XLOOKUP(F13,Sheet1!C:C,Sheet1!B:B,"N/A",0) -> AS | H13: =+_xlfn.XLOOKUP(F13,Sheet1!C:C,Sheet1!D:D,"N/A",0) -> 016
A14: Andorra | B14: STA (AND) | C14: 0.012219834 | D14: =C14*1024 -> 12.51311 | E14: =_xlfn.MINIFS(D:D,A:A,A14,D:D,"<>0") -> 12.51311 | F14: =_xlfn.TEXTBEFORE(_xlfn.TEXTAFTER(B14,"("),")") -> AND | G14: =+_xlfn.XLOOKUP(F14,Sheet1!C:C,Sheet1!B:B,"N/A",0) -> AD | H14: =+_xlfn.XLOOKUP(F14,Sheet1!C:C,Sheet1!D:D,"N/A",0) -> 020
A15: Angola | B15: Africell (AGO) | C15: 0.0016969 | D15: =C15*1024 -> 1.7376256 | E15: =_xlfn.MINIFS(D:D,A:A,A15,D:D,"<>0") -> 1.7376256 | F15: =_xlfn.TEXTBEFORE(_xlfn.TEXTAFTER(B15,"("),")") -> AGO | G15: =+_xlfn.XLOOKUP(F15,Sheet1!C:C,Sheet1!B:B,"N/A",0) -> AO | H15: =+_xlfn.XLOOKUP(F15,Sheet1!C:C,Sheet1!D:D,"N/A",0) -> 024
... A17: Anguilla | B17: Liberty (AIA) | C17: 0.0025454 | D17: =C17*1024 -> 2.6064896 | E17: =_xlfn.MINIFS(D:D,A:A,A17,D:D,"<>0") -> 2.6064896 | F17: =_xlfn.TEXTBEFORE(_xlfn.TEXTAFTER(B17,"("),")") -> AIA | G17: =+_xlfn.XLOOKUP(F17,Sheet1!C:C,Sheet1!B:B,"N/A",0) -> AI | H17: =+_xlfn.XLOOKUP(F17,Sheet1!C:C,Sheet1!D:D,"N/A",0) -> 660
A18: Antigua and Barbuda | B18: APUA (ATG) | D18: =C18*1024 -> 0 | E18: =_xlfn.MINIFS(D:D,A:A,A18,D:D,"<>0") -> 2.6064896 | F18: =_xlfn.TEXTBEFORE(_xlfn.TEXTAFTER(B18,"("),")") -> ATG | G18: =+_xlfn.XLOOKUP(F18,Sheet1!C:C,Sheet1!B:B,"N/A",0) -> AG | H18: =+_xlfn.XLOOKUP(F18,Sheet1!C:C,Sheet1!D:D,"N/A",0) -> 028
A19: Antigua and Barbuda | B19: Liberty (ATG) | C19: 0.0025454 | D19: =C19*1024 -> 2.6064896 | E19: =_xlfn.MINIFS(D:D,A:A,A19,D:D,"<>0") -> 2.6064896 | F19: =_xlfn.TEXTBEFORE(_xlfn.TEXTAFTER(B19,"("),")") -> ATG | G19: =+_xlfn.XLOOKUP(F19,Sheet1!C:C,Sheet1!B:B,"N/A",0) -> AG | H19: =+_xlfn.XLOOKUP(F19,Sheet1!C:C,Sheet1!D:D,"N/A",0) -> 028
A20: Argentina | B20: AMX (ARG) | C20: 0.0019167537 | D20: =C20*1024 -> 1.9627558 | E20: =_xlfn.MINIFS(D:D,A:A,A20,D:D,"<>0") -> 0.868864 | F20: =_xlfn.TEXTBEFORE(_xlfn.TEXTAFTER(B20,"("),")") -> ARG | G20: =+_xlfn.XLOOKUP(F20,Sheet1!C:C,Sheet1!B:B,"N/A",0) -> AR | H20: =+_xlfn.XLOOKUP(F20,Sheet1!C:C,Sheet1!D:D,"N/A",0) -> 032
A21: Argentina | B21: Telecom (ARG) | C21: 0.0008485 | D21: =C21*1024 -> 0.868864 | E21: =_xlfn.MINIFS(D:D,A:A,A21,D:D,"<>0") -> 0.868864 | F21: =_xlfn.TEXTBEFORE(_xlfn.TEXTAFTER(B21,"("),")") -> ARG | G21: =+_xlfn.XLOOKUP(F21,Sheet1!C:C,Sheet1!B:B,"N/A",0) -> AR | H21: =+_xlfn.XLOOKUP(F21,Sheet1!C:C,Sheet1!D:D,"N/A",0) -> 032
A22: Argentina | B22: Telefonica (ARG) | C22: 0.0010300715 | D22: =C22*1024 -> 1.0547932 | E22: =_xlfn.MINIFS(D:D,A:A,A22,D:D,"<>0") -> 0.868864 | F22: =_xlfn.TEXTBEFORE(_xlfn.TEXTAFTER(B22,"("),")") -> ARG | G22: =+_xlfn.XLOOKUP(F22,Sheet1!C:C,Sheet1!B:B,"N/A",0) -> AR | H22: =+_xlfn.XLOOKUP(F22,Sheet1!C:C,Sheet1!D:D,"N/A",0) -> 032
A23: Armenia | B23: MTS (ARM) | C23: 0.0013046198 | D23: =C23*1024 -> 1.3359307 | E23: =_xlfn.MINIFS(D:D,A:A,A23,D:D,"<>0") -> 1.0781847 | F23: =_xlfn.TEXTBEFORE(_xlfn.TEXTAFTER(B23,"("),")") -> ARM | G23: =+_xlfn.XLOOKUP(F23,Sheet1!C:C,Sheet1!B:B,"N/A",0) -> AM | H23: =+_xlfn.XLOOKUP(F23,Sheet1!C:C,Sheet1!D:D,"N/A",0) -> 051
A24: Armenia | B24: Telecom (ARM) | C24: 0.0010529147 | D24: =C24*1024 -> 1.0781847 | E24: =_xlfn.MINIFS(D:D,A:A,A24,D:D,"<>0") -> 1.0781847 | F24: =_xlfn.TEXTBEFORE(_xlfn.TEXTAFTER(B24,"("),")") -> ARM | G24: =+_xlfn.XLOOKUP(F24,Sheet1!C:C,Sheet1!B:B,"N/A",0) -> AM | H24: =+_xlfn.XLOOKUP(F24,Sheet1!C:C,Sheet1!D:D,"N/A",0) -> 051
A25: Armenia | B25: UCom (ARM) | C25: 0.0027681793 | D25: =C25*1024 -> 2.8346156 | E25: =_xlfn.MINIFS(D:D,A:A,A25,D:D,"<>0") -> 1.0781847 | F25: =_xlfn.TEXTBEFORE(_xlfn.TEXTAFTER(B25,"("),")") -> ARM | G25: =+_xlfn.XLOOKUP(F25,Sheet1!C:C,Sheet1!B:B,"N/A",0) -> AM | H25: =+_xlfn.XLOOKUP(F25,Sheet1!C:C,Sheet1!D:D,"N/A",0) -> 051
A26: Aruba | B26: Digicel (ABW) | D26: =C26*1024 -> 0 | E26: =_xlfn.MINIFS(D:D,A:A,A26,D:D,"<>0") -> 6.9506048 | F26: =_xlfn.TEXTBEFORE(_xlfn.TEXTAFTER(B26,"("),")") -> ABW | G26: =+_xlfn.XLOOKUP(F26,Sheet1!C:C,Sheet1!B:B,"N/A",0) -> AW | H26: =+_xlfn.XLOOKUP(F26,Sheet1!C:C,Sheet1!D:D,"N/A",0) -> 533
A27: Aruba | B27: Setar (ABW) | C27: 0.0067877 | D27: =C27*1024 -> 6.9506048 | E27: =_xlfn.MINIFS(D:D,A:A,A27,D:D,"<>0") -> 6.9506048 | F27: =_xlfn.TEXTBEFORE(_xlfn.TEXTAFTER(B27,"("),")") -> ABW | G27: =+_xlfn.XLOOKUP(F27,Sheet1!C:C,Sheet1!B:B,"N/A",0) -> AW | H27: =+_xlfn.XLOOKUP(F27,Sheet1!C:C,Sheet1!D:D,"N/A",0) -> 533
A28: Australia | B28: Optus (AUS) | C28: 0.0008 | D28: =C28*1024 -> 0.8192 | E28: =_xlfn.MINIFS(D:D,A:A,A28,D:D,"<>0") -> 0.512 | F28: =_xlfn.TEXTBEFORE(_xlfn.TEXTAFTER(B28,"("),")") -> AUS | G28: =+_xlfn.XLOOKUP(F28,Sheet1!C:C,Sheet1!B:B,"N/A",0) -> AU | H28: =+_xlfn.XLOOKUP(F28,Sheet1!C:C,Sheet1!D:D,"N/A",0) -> 036
A29: Australia | B29: Telstra (AUS) | C29: 0.0005 | D29: =C29*1024 -> 0.512 | E29: =_xlfn.MINIFS(D:D,A:A,A29,D:D,"<>0") -> 0.512 | F29: =_xlfn.TEXTBEFORE(_xlfn.TEXTAFTER(B29,"("),")") -> AUS | G29: =+_xlfn.XLOOKUP(F29,Sheet1!C:C,Sheet1!B:B,"N/A",0) -> AU | H29: =+_xlfn.XLOOKUP(F29,Sheet1!C:C,Sheet1!D:D,"N/A",0) -> 036
A30: Australia | B30: Vodafone (AUS) | C30: 0.00091515221 | D30: =C30*1024 -> 0.93711586 | E30: =_xlfn.MINIFS(D:D,A:A,A30,D:D,"<>0") -> 0.512 | F30: =_xlfn.TEXTBEFORE(_xlfn.TEXTAFTER(B30,"("),")") -> AUS | G30: =+_xlfn.XLOOKUP(F30,Sheet1!C:C,Sheet1!B:B,"N/A",0) -> AU | H30: =+_xlfn.XLOOKUP(F30,Sheet1!C:C,Sheet1!D:D,"N/A",0) -> 036
A31: Austria | B31: A1 (AUT) | C31: 0.0015 | D31: =C31*1024 -> 1.536 | E31: =_xlfn.MINIFS(D:D,A:A,A31,D:D,"<>0") -> 0.59267841 | F31: =_xlfn.TEXTBEFORE(_xlfn.TEXTAFTER(B31,"("),")") -> AUT | G31: =+_xlfn.XLOOKUP(F31,Sheet1!C:C,Sheet1!B:B,"N/A",0) -> AT | H31: =+_xlfn.XLOOKUP(F31,Sheet1!C:C,Sheet1!D:D,"N/A",0) -> 040
A32: Austria | B32: DT (AUT) | C32: 0.00057878751 | D32: =C32*1024 -> 0.59267841 | E32: =_xlfn.MINIFS(D:D,A:A,A32,D:D,"<>0") -> 0.59267841 | F32: =_xlfn.TEXTBEFORE(_xlfn.TEXTAFTER(B32,"("),")") -> AUT | G32: =+_xlfn.XLOOKUP(F32,Sheet1!C:C,Sheet1!B:B,"N/A",0) -> AT | H32: =+_xlfn.XLOOKUP(F32,Sheet1!C:C,Sheet1!D:D,"N/A",0) -> 040
A33: Austria | B33: H3G (AUT) | C33: 0.0006229 | D33: =C33*1024 -> 0.6378496 | E33: =_xlfn.MINIFS(D:D,A:A,A33,D:D,"<>0") -> 0.59267841 | F33: =_xlfn.TEXTBEFORE(_xlfn.TEXTAFTER(B33,"("),")") -> AUT | G33: =+_xlfn.XLOOKUP(F33,Sheet1!C:C,Sheet1!B:B,"N/A",0) -> AT | H33: =+_xlfn.XLOOKUP(F33,Sheet1!C:C,Sheet1!D:D,"N/A",0) -> 040
A34: Azerbaijan | B34: Azercell (AZE) | C34: 0.0035 | D34: =C34*1024 -> 3.584 | E34: =_xlfn.MINIFS(D:D,A:A,A34,D:D,"<>0") -> 3.0408704 | F34: =_xlfn.TEXTBEFORE(_xlfn.TEXTAFTER(B34,"("),")") -> AZE | G34: =+_xlfn.XLOOKUP(F34,Sheet1!C:C,Sheet1!B:B,"N/A",0) -> AZ | H34: =+_xlfn.XLOOKUP(F34,Sheet1!C:C,Sheet1!D:D,"N/A",0) -> 031
A35: Azerbaijan | B35: Azerfon (AZE) | D35: =C35*1024 -> 0 | E35: =_xlfn.MINIFS(D:D,A:A,A35,D:D,"<>0") -> 3.0408704 | F35: =_xlfn.TEXTBEFORE(_xlfn.TEXTAFTER(B35,"("),")") -> AZE | G35: =+_xlfn.XLOOKUP(F35,Sheet1!C:C,Sheet1!B:B,"N/A",0) -> AZ | H35: =+_xlfn.XLOOKUP(F35,Sheet1!C:C,Sheet1!D:D,"N/A",0) -> 031
A36: Azerbaijan | B36: Bakcell (AZE) | C36: 0.0029696 | D36: =C36*1024 -> 3.0408704 | E36: =_xlfn.MINIFS(D:D,A:A,A36,D:D,"<>0") -> 3.0408704 | F36: =_xlfn.TEXTBEFORE(_xlfn.TEXTAFTER(B36,"("),")") -> AZE | G36: =+_xlfn.XLOOKUP(F36,Sheet1!C:C,Sheet1!B:B,"N/A",0) -> AZ | H36: =+_xlfn.XLOOKUP(F36,Sheet1!C:C,Sheet1!D:D,"N/A",0) -> 031
A37: Bahamas | B37: Aliv (BHS) | C37: 0.0008919315 | D37: =C37*1024 -> 0.91333786 | E37: =_xlfn.MINIFS(D:D,A:A,A37,D:D,"<>0") -> 0.91333786 | F37: =_xlfn.TEXTBEFORE(_xlfn.TEXTAFTER(B37,"("),")") -> BHS | G37: =+_xlfn.XLOOKUP(F37,Sheet1!C:C,Sheet1!B:B,"N/A",0) -> BS | H37: =+_xlfn.XLOOKUP(F37,Sheet1!C:C,Sheet1!D:D,"N/A",0) -> 044
A38: Bahamas | B38: Liberty (BHS) | C38: 0.0025454 | D38: =C38*1024 -> 2.6064896 | E38: =_xlfn.MINIFS(D:D,A:A,A38,D:D,"<>0") -> 0.91333786 | F38: =_xlfn.TEXTBEFORE(_xlfn.TEXTAFTER(B38,"("),")") -> BHS | G38: =+_xlfn.XLOOKUP(F38,Sheet1!C:C,Sheet1!B:B,"N/A",0) -> BS | H38: =+_xlfn.XLOOKUP(F38,Sheet1!C:C,Sheet1!D:D,"N/A",0) -> 044
A39: Bahrain | B39: Batelco (BHR) | C39: 0.0043636106 | D39: =C39*1024 -> 4.4683372 | E39: =_xlfn.MINIFS(D:D,A:A,A39,D:D,"<>0") -> 0.87096874 | F39: =_xlfn.TEXTBEFORE(_xlfn.TEXTAFTER(B39,"("),")") -> BHR | G39: =+_xlfn.XLOOKUP(F39,Sheet1!C:C,Sheet1!B:B,"N/A",0) -> BH | H39: =+_xlfn.XLOOKUP(F39,Sheet1!C:C,Sheet1!D:D,"N/A",0) -> 048
A40: Bahrain | B40: STC (BHR) | C40: 0.0017293 | D40: =C40*1024 -> 1.7708032 | E40: =_xlfn.MINIFS(D:D,A:A,A40,D:D,"<>0") -> 0.87096874 | F40: =_xlfn.TEXTBEFORE(_xlfn.TEXTAFTER(B40,"("),")") -> BHR | G40: =+_xlfn.XLOOKUP(F40,Sheet1!C:C,Sheet1!B:B,"N/A",0) -> BH | H40: =+_xlfn.XLOOKUP(F40,Sheet1!C:C,Sheet1!D:D,"N/A",0) -> 048
A41: Bahrain | B41: ZOI (BHR) | C41: 0.00085055541 | D41: =C41*1024 -> 0.87096874 | E41: =_xlfn.MINIFS(D:D,A:A,A41,D:D,"<>0") -> 0.87096874 | F41: =_xlfn.TEXTBEFORE(_xlfn.TEXTAFTER(B41,"("),")") -> BHR | G41: =+_xlfn.XLOOKUP(F41,Sheet1!C:C,Sheet1!B:B,"N/A",0) -> BH | H41: =+_xlfn.XLOOKUP(F41,Sheet1!C:C,Sheet1!D:D,"N/A",0) -> 048
...

Sheet Sheet1
A1: Country | B1: Alpha-2 code | C1: Alpha-3 code | D1: Numeric
A2: Afghanistan | B2: AF | C2: AFG | D2: 004
A3: Albania | B3: AL | C3: ALB | D3: 008
A4: Algeria | B4: DZ | C4: DZA | D4: 012
A5: American Samoa | B5: AS | C5: ASM | D5: 016
A6: Andorra | B6: AD | C6: AND | D6: 020
A7: Angola | B7: AO | C7: AGO | D7: 024
A8: Anguilla | B8: AI | C8: AIA | D8: 660
A9: Antarctica | B9: AQ | C9: ATA | D9: 010
A10: Antigua and Barbuda | B10: AG | C10: ATG | D10: 028
A11: Argentina | B11: AR | C11: ARG | D11: 032
A12: Armenia | B12: AM | C12: ARM | D12: 051
... A250: Åland Islands | B250: AX | C250: ALA | D250: 248
A251: Kosovo | B251: XK | C251: XKX
