Workbook

Sheet min per Codes
A1: ISO_Code_A2 | B1: ISO_Code_A3 | C1: country | D1: Min of Min
A2: AD | B2: AND | C2: Andorra | D2: 7.845888
A3: AE | B3: ARE | C3: UAE | D3: 2.05824
A4: AF | B4: AFG | C4: Afghanistan | D4: 2.56
A5: AG | B5: ATG | C5: Antigua and Barbuda | D5: 3.072
A6: AI | B6: AIA | C6: Anguilla | D6: 3.072
A7: AL | B7: ALB | C7: Albania | D7: 1.040384
A8: AM | B8: ARM | C8: Armenia | D8: 1.024
A9: AO | B9: AGO | C9: Angola | D9: 1.968128
A10: AR | B10: ARG | C10: Argentina | D10: 1.024
A11: AT | B11: AUT | C11: Austria | D11: 0.636928
A12: AU | B12: AUS | C12: Australia | D12: 0.512
A13: AW | B13: ABW | C13: Aruba | D13: 8.192
... A179: ZW | B179: ZWE | C179: Zimbabwe | D179: 5.15584
A180: Grand Total | D180: 0

Sheet EU_Regions
A1: no | B1: Region | C1: RegionISO3 | D1: CountriesISO3 | E1: Country1 | F1: Country2 | G1: Country3 | H1: RegionISO3 | I1: CountriesISO3 | J1: Cost1 | K1: Cost2 | L1: Cost3 | M1: STDV | N1: CV Coefficient of Variation | O1: Range
A2: 1 | B2: Iberia | C2: =+H2 -> ESPPRT | D2: =+I2 -> ["ESP", "PRT"] | E2: Spain | F2: Portugal | H2: =_xlfn.CONCAT(_xlfn.XLOOKUP(TRIM(E2),'min per Codes'!C:C,'min per Codes'!B:B,"",0),_xlfn.XLOOKUP(TRIM(F2),'min per Codes'!C:C,'min per Codes'!B:B,""),_xlfn.XLOOKUP(TRIM(G2),'min per Codes'!C:C,'min per Codes'!B:B,"")) -> ESPPRT | I2: =+"["""&_xlfn.CONCAT(_xlfn.XLOOKUP(TRIM(E2),'min per Codes'!C:C,'min per Codes'!B:B,"",0),""", """,_xlfn.XLOOKUP(TRIM(F2),'min per Codes'!C:C,'min per Codes'!B:B,""),IF(G2="",_xlfn.XLOOKUP(TRIM(G2),'min per Codes'!C:C,'min per Codes'!B:B,"")&"""]",""", """&_xlfn.XLOOKUP(TRIM(G2),'min per Codes'!C:C,'min per Codes'!B:B,"")&"""]")) -> ["ESP", "PRT"] | J2: =+_xlfn.XLOOKUP(E2,'min per Codes'!$C:$C,'min per Codes'!$D:$D,0,) -> 0.7168 | K2: =+_xlfn.XLOOKUP(F2,'min per Codes'!$C:$C,'min per Codes'!$D:$D,0,) -> 0.513024 | L2: =+_xlfn.XLOOKUP(G2,'min per Codes'!$C:$C,'min per Codes'!$D:$D,0,) -> 0 | M2: {=+_xlfn.STDEV.S(_xlfn._xlws.FILTER(J2:L2,J2:L2<>0))} -> 0.14409139 | N2: {=+M2/AVERAGE(_xlfn._xlws.FILTER(J2:L2,J2:L2<>0))} -> 0.23432848 | O2: {=+MAX(_xlfn._xlws.FILTER(J2:L2,J2:L2<>0))/MIN(_xlfn._xlws.FILTER(J2:L2,J2:L2<>0))} -> 1.3972056
A3: 2 | B3: Benelux | C3: =+H3 -> BELNLDLUX | D3: =+I3 -> ["BEL", "NLD", "LUX"] | E3: Belgium | F3: Netherlands | G3: Luxembourg | H3: =_xlfn.CONCAT(_xlfn.XLOOKUP(TRIM(E3),'min per Codes'!C:C,'min per Codes'!B:B,"",0),_xlfn.XLOOKUP(TRIM(F3),'min per Codes'!C:C,'min per Codes'!B:B,""),_xlfn.XLOOKUP(TRIM(G3),'min per Codes'!C:C,'min per Codes'!B:B,"")) -> BELNLDLUX | I3: =+"["""&_xlfn.CONCAT(_xlfn.XLOOKUP(TRIM(E3),'min per Codes'!C:C,'min per Codes'!B:B,"",0),""", """,_xlfn.XLOOKUP(TRIM(F3),'min per Codes'!C:C,'min per Codes'!B:B,""),IF(G3="",_xlfn.XLOOKUP(TRIM(G3),'min per Codes'!C:C,'min per Codes'!B:B,"")&"""]",""", """&_xlfn.XLOOKUP(TRIM(G3),'min per Codes'!C:C,'min per Codes'!B:B,"")&"""]")) -> ["BEL", "NLD", "LUX"] | J3: =+_xlfn.XLOOKUP(E3,'min per Codes'!$C:$C,'min per Codes'!$D:$D,0,) -> 0.421888 | K3: =+_xlfn.XLOOKUP(F3,'min per Codes'!$C:$C,'min per Codes'!$D:$D,0,) -> 0.4096 | L3: =+_xlfn.XLOOKUP(G3,'min per Codes'!$C:$C,'min per Codes'!$D:$D,0,) -> 0.421888 | M3: {=+_xlfn.STDEV.S(_xlfn._xlws.FILTER(J3:L3,J3:L3<>0))} -> 0.0070944801 | N3: {=+M3/AVERAGE(_xlfn._xlws.FILTER(J3:L3,J3:L3<>0))} -> 0.01698089 | O3: {=+MAX(_xlfn._xlws.FILTER(J3:L3,J3:L3<>0))/MIN(_xlfn._xlws.FILTER(J3:L3,J3:L3<>0))} -> 1.03
A4: 3 | B4: Scandinavia | C4: =+H4 -> DNKNORSWE | D4: =+I4 -> ["DNK", "NOR", "SWE"] | E4: Denmark | F4: Norway | G4: Sweden | H4: =_xlfn.CONCAT(_xlfn.XLOOKUP(TRIM(E4),'min per Codes'!C:C,'min per Codes'!B:B,"",0),_xlfn.XLOOKUP(TRIM(F4),'min per Codes'!C:C,'min per Codes'!B:B,""),_xlfn.XLOOKUP(TRIM(G4),'min per Codes'!C:C,'min per Codes'!B:B,"")) -> DNKNORSWE | I4: =+"["""&_xlfn.CONCAT(_xlfn.XLOOKUP(TRIM(E4),'min per Codes'!C:C,'min per Codes'!B:B,"",0),""", """,_xlfn.XLOOKUP(TRIM(F4),'min per Codes'!C:C,'min per Codes'!B:B,""),IF(G4="",_xlfn.XLOOKUP(TRIM(G4),'min per Codes'!C:C,'min per Codes'!B:B,"")&"""]",""", """&_xlfn.XLOOKUP(TRIM(G4),'min per Codes'!C:C,'min per Codes'!B:B,"")&"""]")) -> ["DNK", "NOR", "SWE"] | J4: =+_xlfn.XLOOKUP(E4,'min per Codes'!$C:$C,'min per Codes'!$D:$D,0,) -> 0.26112 | K4: =+_xlfn.XLOOKUP(F4,'min per Codes'!$C:$C,'min per Codes'!$D:$D,0,) -> 0.26112 | L4: =+_xlfn.XLOOKUP(G4,'min per Codes'!$C:$C,'min per Codes'!$D:$D,0,) -> 0.26112 | M4: {=+_xlfn.STDEV.S(_xlfn._xlws.FILTER(J4:L4,J4:L4<>0))} -> 0 | N4: {=+M4/AVERAGE(_xlfn._xlws.FILTER(J4:L4,J4:L4<>0))} -> 0 | O4: {=+MAX(_xlfn._xlws.FILTER(J4:L4,J4:L4<>0))/MIN(_xlfn._xlws.FILTER(J4:L4,J4:L4<>0))} -> 1
A5: 4 | B5: North-Baltic | C5: =+H5 -> FINEST | D5: =+I5 -> ["FIN", "EST"] | E5: Finland | F5: Estonia | H5: =_xlfn.CONCAT(_xlfn.XLOOKUP(TRIM(E5),'min per Codes'!C:C,'min per Codes'!B:B,"",0),_xlfn.XLOOKUP(TRIM(F5),'min per Codes'!C:C,'min per Codes'!B:B,""),_xlfn.XLOOKUP(TRIM(G5),'min per Codes'!C:C,'min per Codes'!B:B,"")) -> FINEST | I5: =+"["""&_xlfn.CONCAT(_xlfn.XLOOKUP(TRIM(E5),'min per Codes'!C:C,'min per Codes'!B:B,"",0),""", """,_xlfn.XLOOKUP(TRIM(F5),'min per Codes'!C:C,'min per Codes'!B:B,""),IF(G5="",_xlfn.XLOOKUP(TRIM(G5),'min per Codes'!C:C,'min per Codes'!B:B,"")&"""]",""", """&_xlfn.XLOOKUP(TRIM(G5),'min per Codes'!C:C,'min per Codes'!B:B,"")&"""]")) -> ["FIN", "EST"] | J5: =+_xlfn.XLOOKUP(E5,'min per Codes'!$C:$C,'min per Codes'!$D:$D,0,) -> 0.26112 | K5: =+_xlfn.XLOOKUP(F5,'min per Codes'!$C:$C,'min per Codes'!$D:$D,0,) -> 0.3072 | L5: =+_xlfn.XLOOKUP(G5,'min per Codes'!$C:$C,'min per Codes'!$D:$D,0,) -> 0 | M5: {=+_xlfn.STDEV.S(_xlfn._xlws.FILTER(J5:L5,J5:L5<>0))} -> 0.03258348 | N5: {=+M5/AVERAGE(_xlfn._xlws.FILTER(J5:L5,J5:L5<>0))} -> 0.11466596 | O5: {=+MAX(_xlfn._xlws.FILTER(J5:L5,J5:L5<>0))/MIN(_xlfn._xlws.FILTER(J5:L5,J5:L5<>0))} -> 1.1764706
A6: 5 | B6: Baltic | C6: =+H6 -> LVALTU | D6: =+I6 -> ["LVA", "LTU"] | E6: Latvia | F6: Lithuania | H6: =_xlfn.CONCAT(_xlfn.XLOOKUP(TRIM(E6),'min per Codes'!C:C,'min per Codes'!B:B,"",0),_xlfn.XLOOKUP(TRIM(F6),'min per Codes'!C:C,'min per Codes'!B:B,""),_xlfn.XLOOKUP(TRIM(G6),'min per Codes'!C:C,'min per Codes'!B:B,"")) -> LVALTU | I6: =+"["""&_xlfn.CONCAT(_xlfn.XLOOKUP(TRIM(E6),'min per Codes'!C:C,'min per Codes'!B:B,"",0),""", """,_xlfn.XLOOKUP(TRIM(F6),'min per Codes'!C:C,'min per Codes'!B:B,""),IF(G6="",_xlfn.XLOOKUP(TRIM(G6),'min per Codes'!C:C,'min per Codes'!B:B,"")&"""]",""", """&_xlfn.XLOOKUP(TRIM(G6),'min per Codes'!C:C,'min per Codes'!B:B,"")&"""]")) -> ["LVA", "LTU"] | J6: =+_xlfn.XLOOKUP(E6,'min per Codes'!$C:$C,'min per Codes'!$D:$D,0,) -> 0.2048 | K6: =+_xlfn.XLOOKUP(F6,'min per Codes'!$C:$C,'min per Codes'!$D:$D,0,) -> 0.2048 | L6: =+_xlfn.XLOOKUP(G6,'min per Codes'!$C:$C,'min per Codes'!$D:$D,0,) -> 0 | M6: {=+_xlfn.STDEV.S(_xlfn._xlws.FILTER(J6:L6,J6:L6<>0))} -> 0 | N6: {=+M6/AVERAGE(_xlfn._xlws.FILTER(J6:L6,J6:L6<>0))} -> 0 | O6: {=+MAX(_xlfn._xlws.FILTER(J6:L6,J6:L6<>0))/MIN(_xlfn._xlws.FILTER(J6:L6,J6:L6<>0))} -> 1
A7: 6 | B7: Hellenic | C7: =+H7 -> GRCCYP | D7: =+I7 -> ["GRC", "CYP"] | E7: Greece | F7: Cyprus | H7: =_xlfn.CONCAT(_xlfn.XLOOKUP(TRIM(E7),'min per Codes'!C:C,'min per Codes'!B:B,"",0),_xlfn.XLOOKUP(TRIM(F7),'min per Codes'!C:C,'min per Codes'!B:B,""),_xlfn.XLOOKUP(TRIM(G7),'min per Codes'!C:C,'min per Codes'!B:B,"")) -> GRCCYP | I7: =+"["""&_xlfn.CONCAT(_xlfn.XLOOKUP(TRIM(E7),'min per Codes'!C:C,'min per Codes'!B:B,"",0),""", """,_xlfn.XLOOKUP(TRIM(F7),'min per Codes'!C:C,'min per Codes'!B:B,""),IF(G7="",_xlfn.XLOOKUP(TRIM(G7),'min per Codes'!C:C,'min per Codes'!B:B,"")&"""]",""", """&_xlfn.XLOOKUP(TRIM(G7),'min per Codes'!C:C,'min per Codes'!B:B,"")&"""]")) -> ["GRC", "CYP"] | J7: =+_xlfn.XLOOKUP(E7,'min per Codes'!$C:$C,'min per Codes'!$D:$D,0,) -> 0.784384 | K7: =+_xlfn.XLOOKUP(F7,'min per Codes'!$C:$C,'min per Codes'!$D:$D,0,) -> 0.256 | L7: =+_xlfn.XLOOKUP(G7,'min per Codes'!$C:$C,'min per Codes'!$D:$D,0,) -> 0 | M7: {=+_xlfn.STDEV.S(_xlfn._xlws.FILTER(J7:L7,J7:L7<>0))} -> 0.37362391 | N7: {=+M7/AVERAGE(_xlfn._xlws.FILTER(J7:L7,J7:L7<>0))} -> 0.71824232 | O7: {=+MAX(_xlfn._xlws.FILTER(J7:L7,J7:L7<>0))/MIN(_xlfn._xlws.FILTER(J7:L7,J7:L7<>0))} -> 3.064
A8: 7 | B8: Dacothrace | C8: =+H8 -> ROUBGR | D8: =+I8 -> ["ROU", "BGR"] | E8: Romania | F8: Bulgaria | H8: =_xlfn.CONCAT(_xlfn.XLOOKUP(TRIM(E8),'min per Codes'!C:C,'min per Codes'!B:B,"",0),_xlfn.XLOOKUP(TRIM(F8),'min per Codes'!C:C,'min per Codes'!B:B,""),_xlfn.XLOOKUP(TRIM(G8),'min per Codes'!C:C,'min per Codes'!B:B,"")) -> ROUBGR | I8: =+"["""&_xlfn.CONCAT(_xlfn.XLOOKUP(TRIM(E8),'min per Codes'!C:C,'min per Codes'!B:B,"",0),""", """,_xlfn.XLOOKUP(TRIM(F8),'min per Codes'!C:C,'min per Codes'!B:B,""),IF(G8="",_xlfn.XLOOKUP(TRIM(G8),'min per Codes'!C:C,'min per Codes'!B:B,"")&"""]",""", """&_xlfn.XLOOKUP(TRIM(G8),'min per Codes'!C:C,'min per Codes'!B:B,"")&"""]")) -> ["ROU", "BGR"] | J8: =+_xlfn.XLOOKUP(E8,'min per Codes'!$C:$C,'min per Codes'!$D:$D,0,) -> 0.233472 | K8: =+_xlfn.XLOOKUP(F8,'min per Codes'!$C:$C,'min per Codes'!$D:$D,0,) -> 0.530432 | L8: =+_xlfn.XLOOKUP(G8,'min per Codes'!$C:$C,'min per Codes'!$D:$D,0,) -> 0 | M8: {=+_xlfn.STDEV.S(_xlfn._xlws.FILTER(J8:L8,J8:L8<>0))} -> 0.20998243 | N8: {=+M8/AVERAGE(_xlfn._xlws.FILTER(J8:L8,J8:L8<>0))} -> 0.5497613 | O8: {=+MAX(_xlfn._xlws.FILTER(J8:L8,J8:L8<>0))/MIN(_xlfn._xlws.FILTER(J8:L8,J8:L8<>0))} -> 2.2719298
A9: 8 | B9: Alpe-Adria | C9: =+H9 -> AUTHRVSVN | D9: =+I9 -> ["AUT", "HRV", "SVN"] | E9: Austria | F9: Croatia | G9: Slovenia | H9: =_xlfn.CONCAT(_xlfn.XLOOKUP(TRIM(E9),'min per Codes'!C:C,'min per Codes'!B:B,"",0),_xlfn.XLOOKUP(TRIM(F9),'min per Codes'!C:C,'min per Codes'!B:B,""),_xlfn.XLOOKUP(TRIM(G9),'min per Codes'!C:C,'min per Codes'!B:B,"")) -> AUTHRVSVN | I9: =+"["""&_xlfn.CONCAT(_xlfn.XLOOKUP(TRIM(E9),'min per Codes'!C:C,'min per Codes'!B:B,"",0),""", """,_xlfn.XLOOKUP(TRIM(F9),'min per Codes'!C:C,'min per Codes'!B:B,""),IF(G9="",_xlfn.XLOOKUP(TRIM(G9),'min per Codes'!C:C,'min per Codes'!B:B,"")&"""]",""", """&_xlfn.XLOOKUP(TRIM(G9),'min per Codes'!C:C,'min per Codes'!B:B,"")&"""]")) -> ["AUT", "HRV", "SVN"] | J9: =+_xlfn.XLOOKUP(E9,'min per Codes'!$C:$C,'min per Codes'!$D:$D,0,) -> 0.636928 | K9: 0 | L9: =+_xlfn.XLOOKUP(G9,'min per Codes'!$C:$C,'min per Codes'!$D:$D,0,) -> 0.595968 | M9: {=+_xlfn.STDEV.S(_xlfn._xlws.FILTER(J9:L9,J9:L9<>0))} -> 0.028963094 | N9: {=+M9/AVERAGE(_xlfn._xlws.FILTER(J9:L9,J9:L9<>0))} -> 0.046983839 | O9: {=+MAX(_xlfn._xlws.FILTER(J9:L9,J9:L9<>0))/MIN(_xlfn._xlws.FILTER(J9:L9,J9:L9<>0))} -> 1.0687285
A10: 9 | B10: Ger-Vad | C10: =+H10 -> DEULIE | D10: =+I10 -> ["DEU", "LIE"] | E10: Germany | F10: Liechtenstein | H10: =_xlfn.CONCAT(_xlfn.XLOOKUP(TRIM(E10),'min per Codes'!C:C,'min per Codes'!B:B,"",0),_xlfn.XLOOKUP(TRIM(F10),'min per Codes'!C:C,'min per Codes'!B:B,""),_xlfn.XLOOKUP(TRIM(G10),'min per Codes'!C:C,'min per Codes'!B:B,"")) -> DEULIE | I10: =+"["""&_xlfn.CONCAT(_xlfn.XLOOKUP(TRIM(E10),'min per Codes'!C:C,'min per Codes'!B:B,"",0),""", """,_xlfn.XLOOKUP(TRIM(F10),'min per Codes'!C:C,'min per Codes'!B:B,""),IF(G10="",_xlfn.XLOOKUP(TRIM(G10),'min per Codes'!C:C,'min per Codes'!B:B,"")&"""]",""", """&_xlfn.XLOOKUP(TRIM(G10),'min per Codes'!C:C,'min per Codes'!B:B,"")&"""]")) -> ["DEU", "LIE"] | J10: =+_xlfn.XLOOKUP(E10,'min per Codes'!$C:$C,'min per Codes'!$D:$D,0,) -> 0.7168 | K10: =+_xlfn.XLOOKUP(F10,'min per Codes'!$C:$C,'min per Codes'!$D:$D,0,) -> 0.636928 | L10: =+_xlfn.XLOOKUP(G10,'min per Codes'!$C:$C,'min per Codes'!$D:$D,0,) -> 0 | M10: {=+_xlfn.STDEV.S(_xlfn._xlws.FILTER(J10:L10,J10:L10<>0))} -> 0.056478033 | N10: {=+M10/AVERAGE(_xlfn._xlws.FILTER(J10:L10,J10:L10<>0))} -> 0.08344074 | O10: {=+MAX(_xlfn._xlws.FILTER(J10:L10,J10:L10<>0))/MIN(_xlfn._xlws.FILTER(J10:L10,J10:L10<>0))} -> 1.1254019
A11: 10 | B11: ItalMalta | C11: =+H11 -> ITAMLT | D11: =+I11 -> ["ITA", "MLT"] | E11: Italy | F11: Malta | H11: =_xlfn.CONCAT(_xlfn.XLOOKUP(TRIM(E11),'min per Codes'!C:C,'min per Codes'!B:B,"",0),_xlfn.XLOOKUP(TRIM(F11),'min per Codes'!C:C,'min per Codes'!B:B,""),_xlfn.XLOOKUP(TRIM(G11),'min per Codes'!C:C,'min per Codes'!B:B,"")) -> ITAMLT | I11: =+"["""&_xlfn.CONCAT(_xlfn.XLOOKUP(TRIM(E11),'min per Codes'!C:C,'min per Codes'!B:B,"",0),""", """,_xlfn.XLOOKUP(TRIM(F11),'min per Codes'!C:C,'min per Codes'!B:B,""),IF(G11="",_xlfn.XLOOKUP(TRIM(G11),'min per Codes'!C:C,'min per Codes'!B:B,"")&"""]",""", """&_xlfn.XLOOKUP(TRIM(G11),'min per Codes'!C:C,'min per Codes'!B:B,"")&"""]")) -> ["ITA", "MLT"] | J11: =+_xlfn.XLOOKUP(E11,'min per Codes'!$C:$C,'min per Codes'!$D:$D,0,) -> 0.550912 | K11: =+_xlfn.XLOOKUP(F11,'min per Codes'!$C:$C,'min per Codes'!$D:$D,0,) -> 0.19456 | L11: =+_xlfn.XLOOKUP(G11,'min per Codes'!$C:$C,'min per Codes'!$D:$D,0,) -> 0 | M11: {=+_xlfn.STDEV.S(_xlfn._xlws.FILTER(J11:L11,J11:L11<>0))} -> 0.25197892 | N11: {=+M11/AVERAGE(_xlfn._xlws.FILTER(J11:L11,J11:L11<>0))} -> 0.67602516 | O11: {=+MAX(_xlfn._xlws.FILTER(J11:L11,J11:L11<>0))/MIN(_xlfn._xlws.FILTER(J11:L11,J11:L11<>0))} -> 2.8315789
A12: 11 | B12: BoPolia | C12: =+H12 -> POLCZE | D12: =+I12 -> ["POL", "CZE"] | E12: Poland | F12: Czech Republic | H12: =_xlfn.CONCAT(_xlfn.XLOOKUP(TRIM(E12),'min per Codes'!C:C,'min per Codes'!B:B,"",0),_xlfn.XLOOKUP(TRIM(F12),'min per Codes'!C:C,'min per Codes'!B:B,""),_xlfn.XLOOKUP(TRIM(G12),'min per Codes'!C:C,'min per Codes'!B:B,"")) -> POLCZE | I12: =+"["""&_xlfn.CONCAT(_xlfn.XLOOKUP(TRIM(E12),'min per Codes'!C:C,'min per Codes'!B:B,"",0),""", """,_xlfn.XLOOKUP(TRIM(F12),'min per Codes'!C:C,'min per Codes'!B:B,""),IF(G12="",_xlfn.XLOOKUP(TRIM(G12),'min per Codes'!C:C,'min per Codes'!B:B,"")&"""]",""", """&_xlfn.XLOOKUP(TRIM(G12),'min per Codes'!C:C,'min per Codes'!B:B,"")&"""]")) -> ["POL", "CZE"] | J12: =+_xlfn.XLOOKUP(E12,'min per Codes'!$C:$C,'min per Codes'!$D:$D,0,) -> 0.550912 | K12: =+_xlfn.XLOOKUP(F12,'min per Codes'!$C:$C,'min per Codes'!$D:$D,0,) -> 0.530432 | L12: =+_xlfn.XLOOKUP(G12,'min per Codes'!$C:$C,'min per Codes'!$D:$D,0,) -> 0 | M12: {=+_xlfn.STDEV.S(_xlfn._xlws.FILTER(J12:L12,J12:L12<>0))} -> 0.014481547 | N12: {=+M12/AVERAGE(_xlfn._xlws.FILTER(J12:L12,J12:L12<>0))} -> 0.026784348 | O12: {=+MAX(_xlfn._xlws.FILTER(J12:L12,J12:L12<>0))/MIN(_xlfn._xlws.FILTER(J12:L12,J12:L12<>0))} -> 1.03861
A13: 12 | B13: Pannonia | C13: =+H13 -> SVKHUN | D13: =+I13 -> ["SVK", "HUN"] | E13: Slovak Republic | F13: Hungary | H13: =_xlfn.CONCAT(_xlfn.XLOOKUP(TRIM(E13),'min per Codes'!C:C,'min per Codes'!B:B,"",0),_xlfn.XLOOKUP(TRIM(F13),'min per Codes'!C:C,'min per Codes'!B:B,""),_xlfn.XLOOKUP(TRIM(G13),'min per Codes'!C:C,'min per Codes'!B:B,"")) -> SVKHUN | I13: =+"["""&_xlfn.CONCAT(_xlfn.XLOOKUP(TRIM(E13),'min per Codes'!C:C,'min per Codes'!B:B,"",0),""", """,_xlfn.XLOOKUP(TRIM(F13),'min per Codes'!C:C,'min per Codes'!B:B,""),IF(G13="",_xlfn.XLOOKUP(TRIM(G13),'min per Codes'!C:C,'min per Codes'!B:B,"")&"""]",""", """&_xlfn.XLOOKUP(TRIM(G13),'min per Codes'!C:C,'min per Codes'!B:B,"")&"""]")) -> ["SVK", "HUN"] | J13: =+_xlfn.XLOOKUP(E13,'min per Codes'!$C:$C,'min per Codes'!$D:$D,0,) -> 0.530432 | K13: =+_xlfn.XLOOKUP(F13,'min per Codes'!$C:$C,'min per Codes'!$D:$D,0,) -> 0.530432 | L13: =+_xlfn.XLOOKUP(G13,'min per Codes'!$C:$C,'min per Codes'!$D:$D,0,) -> 0 | M13: {=+_xlfn.STDEV.S(_xlfn._xlws.FILTER(J13:L13,J13:L13<>0))} -> 0 | N13: {=+M13/AVERAGE(_xlfn._xlws.FILTER(J13:L13,J13:L13<>0))} -> 0 | O13: {=+MAX(_xlfn._xlws.FILTER(J13:L13,J13:L13<>0))/MIN(_xlfn._xlws.FILTER(J13:L13,J13:L13<>0))} -> 1
A14: 13 | B14: Hyperborea | C14: =+H14 -> GBRIRLISL | D14: =+I14 -> ["GBR", "IRL", "ISL"] | E14: UK | F14: Ireland | G14: Iceland | H14: =_xlfn.CONCAT(_xlfn.XLOOKUP(TRIM(E14),'min per Codes'!C:C,'min per Codes'!B:B,"",0),_xlfn.XLOOKUP(TRIM(F14),'min per Codes'!C:C,'min per Codes'!B:B,""),_xlfn.XLOOKUP(TRIM(G14),'min per Codes'!C:C,'min per Codes'!B:B,"")) -> GBRIRLISL | I14: =+"["""&_xlfn.CONCAT(_xlfn.XLOOKUP(TRIM(E14),'min per Codes'!C:C,'min per Codes'!B:B,"",0),""", """,_xlfn.XLOOKUP(TRIM(F14),'min per Codes'!C:C,'min per Codes'!B:B,""),IF(G14="",_xlfn.XLOOKUP(TRIM(G14),'min per Codes'!C:C,'min per Codes'!B:B,"")&"""]",""", """&_xlfn.XLOOKUP(TRIM(G14),'min per Codes'!C:C,'min per Codes'!B:B,"")&"""]")) -> ["GBR", "IRL", "ISL"] | J14: =+_xlfn.XLOOKUP(E14,'min per Codes'!$C:$C,'min per Codes'!$D:$D,0,) -> 0.418816 | K14: =+_xlfn.XLOOKUP(F14,'min per Codes'!$C:$C,'min per Codes'!$D:$D,0,) -> 0.57344 | L14: =+_xlfn.XLOOKUP(G14,'min per Codes'!$C:$C,'min per Codes'!$D:$D,0,) -> 0.318464 | M14: {=+_xlfn.STDEV.S(_xlfn._xlws.FILTER(J14:L14,J14:L14<>0))} -> 0.12844705 | N14: {=+M14/AVERAGE(_xlfn._xlws.FILTER(J14:L14,J14:L14<>0))} -> 0.29399196 | O14: {=+MAX(_xlfn._xlws.FILTER(J14:L14,J14:L14<>0))/MIN(_xlfn._xlws.FILTER(J14:L14,J14:L14<>0))} -> 1.8006431
A15: 14 | B15: Fran-Suisse | C15: =+H15 -> FRACHE | D15: =+I15 -> ["FRA", "CHE"] | E15: France | F15: Switzerland | H15: =_xlfn.CONCAT(_xlfn.XLOOKUP(TRIM(E15),'min per Codes'!C:C,'min per Codes'!B:B,"",0),_xlfn.XLOOKUP(TRIM(F15),'min per Codes'!C:C,'min per Codes'!B:B,""),_xlfn.XLOOKUP(TRIM(G15),'min per Codes'!C:C,'min per Codes'!B:B,"")) -> FRACHE | I15: =+"["""&_xlfn.CONCAT(_xlfn.XLOOKUP(TRIM(E15),'min per Codes'!C:C,'min per Codes'!B:B,"",0),""", """,_xlfn.XLOOKUP(TRIM(F15),'min per Codes'!C:C,'min per Codes'!B:B,""),IF(G15="",_xlfn.XLOOKUP(TRIM(G15),'min per Codes'!C:C,'min per Codes'!B:B,"")&"""]",""", """&_xlfn.XLOOKUP(TRIM(G15),'min per Codes'!C:C,'min per Codes'!B:B,"")&"""]")) -> ["FRA", "CHE"] | J15: =+_xlfn.XLOOKUP(E15,'min per Codes'!$C:$C,'min per Codes'!$D:$D,0,) -> 0.446464 | K15: =+_xlfn.XLOOKUP(F15,'min per Codes'!$C:$C,'min per Codes'!$D:$D,0,) -> 0.530432 | L15: =+_xlfn.XLOOKUP(G15,'min per Codes'!$C:$C,'min per Codes'!$D:$D,0,) -> 0 | M15: {=+_xlfn.STDEV.S(_xlfn._xlws.FILTER(J15:L15,J15:L15<>0))} -> 0.059374342 | N15: {=+M15/AVERAGE(_xlfn._xlws.FILTER(J15:L15,J15:L15<>0))} -> 0.12155714 | O15: {=+MAX(_xlfn._xlws.FILTER(J15:L15,J15:L15<>0))/MIN(_xlfn._xlws.FILTER(J15:L15,J15:L15<>0))} -> 1.1880734

Sheet Query result
A1: service | B1: direction | C1: operator_name | D1: country | E1: dIOT (MB) | F1: dIOT (GB) | G1: Min | H1: ISO_Code_A3 | I1: ISO_Code_A2 | J1: ISO_Code_Numeric
A2: PSD | B2: Outbound | C2: AeroMobile (AAA) | D2: Aerospace | E2: 0.589502 | F2: =E2*1024 -> 603.65005 | G2: =_xlfn.MINIFS(F:F,D:D,D2,F:F,"<>0") -> 603.65005 | H2: =_xlfn.TEXTBEFORE(_xlfn.TEXTAFTER(C2,"("),")") -> AAA | I2: AA | J2: =+_xlfn.XLOOKUP(H2,Sheet1!C:C,Sheet1!D:D,"N/A",0) -> N/A
A3: PSD | B3: Outbound | C3: Afghan Wireless (AFG) | D3: Afghanistan | E3: 0.004 | F3: =E3*1024 -> 4.096 | G3: =_xlfn.MINIFS(F:F,D:D,D3,F:F,"<>0") -> 2.56 | H3: =_xlfn.TEXTBEFORE(_xlfn.TEXTAFTER(C3,"("),")") -> AFG | I3: =+_xlfn.XLOOKUP(H3,Sheet1!C:C,Sheet1!B:B,"N/A",0) -> AF | J3: =+_xlfn.XLOOKUP(H3,Sheet1!C:C,Sheet1!D:D,"N/A",0) -> 004
A4: PSD | B4: Outbound | C4: Roshan (AFG) | D4: Afghanistan | E4: 0.0025 | F4: =E4*1024 -> 2.56 | G4: =_xlfn.MINIFS(F:F,D:D,D4,F:F,"<>0") -> 2.56 | H4: =_xlfn.TEXTBEFORE(_xlfn.TEXTAFTER(C4,"("),")") -> AFG | I4: =+_xlfn.XLOOKUP(H4,Sheet1!C:C,Sheet1!B:B,"N/A",0) -> AF | J4: =+_xlfn.XLOOKUP(H4,Sheet1!C:C,Sheet1!D:D,"N/A",0) -> 004
A5: PSD | B5: Outbound | C5: Vodafone (ALB) | D5: Albania | E5: 0.001116 | F5: =E5*1024 -> 1.142784 | G5: =_xlfn.MINIFS(F:F,D:D,D5,F:F,"<>0") -> 1.040384 | H5: =_xlfn.TEXTBEFORE(_xlfn.TEXTAFTER(C5,"("),")") -> ALB | I5: =+_xlfn.XLOOKUP(H5,Sheet1!C:C,Sheet1!B:B,"N/A",0) -> AL | J5: =+_xlfn.XLOOKUP(H5,Sheet1!C:C,Sheet1!D:D,"N/A",0) -> 008
A6: PSD | B6: Outbound | C6: One Albania (ALB) 1 | D6: Albania | E6: 0.001016 | F6: =E6*1024 -> 1.040384 | G6: =_xlfn.MINIFS(F:F,D:D,D6,F:F,"<>0") -> 1.040384 | H6: =_xlfn.TEXTBEFORE(_xlfn.TEXTAFTER(C6,"("),")") -> ALB | I6: =+_xlfn.XLOOKUP(H6,Sheet1!C:C,Sheet1!B:B,"N/A",0) -> AL | J6: =+_xlfn.XLOOKUP(H6,Sheet1!C:C,Sheet1!D:D,"N/A",0) -> 008
A7: PSD | B7: Outbound | C7: ATM (DZA) | D7: Algeria | E7: 0.001 | F7: =E7*1024 -> 1.024 | G7: =_xlfn.MINIFS(F:F,D:D,D7,F:F,"<>0") -> 1.024 | H7: =_xlfn.TEXTBEFORE(_xlfn.TEXTAFTER(C7,"("),")") -> DZA | I7: =+_xlfn.XLOOKUP(H7,Sheet1!C:C,Sheet1!B:B,"N/A",0) -> DZ | J7: =+_xlfn.XLOOKUP(H7,Sheet1!C:C,Sheet1!D:D,"N/A",0) -> 012
A8: PSD | B8: Outbound | C8: Ooredoo (DZA) | D8: Algeria | E8: 0.002262 | F8: =E8*1024 -> 2.316288 | G8: =_xlfn.MINIFS(F:F,D:D,D8,F:F,"<>0") -> 1.024 | H8: =_xlfn.TEXTBEFORE(_xlfn.TEXTAFTER(C8,"("),")") -> DZA | I8: =+_xlfn.XLOOKUP(H8,Sheet1!C:C,Sheet1!B:B,"N/A",0) -> DZ | J8: =+_xlfn.XLOOKUP(H8,Sheet1!C:C,Sheet1!D:D,"N/A",0) -> 012
A9: PSD | B9: Outbound | C9: Veon (DZA) | D9: Algeria | E9: 0.009 | F9: =E9*1024 -> 9.216 | G9: =_xlfn.MINIFS(F:F,D:D,D9,F:F,"<>0") -> 1.024 | H9: =_xlfn.TEXTBEFORE(_xlfn.TEXTAFTER(C9,"("),")") -> DZA | I9: =+_xlfn.XLOOKUP(H9,Sheet1!C:C,Sheet1!B:B,"N/A",0) -> DZ | J9: =+_xlfn.XLOOKUP(H9,Sheet1!C:C,Sheet1!D:D,"N/A",0) -> 012
A10: PSD | B10: Outbound | C10: STA (AND) | D10: Andorra | E10: 0.007662 | F10: =E10*1024 -> 7.845888 | G10: =_xlfn.MINIFS(F:F,D:D,D10,F:F,"<>0") -> 7.845888 | H10: =_xlfn.TEXTBEFORE(_xlfn.TEXTAFTER(C10,"("),")") -> AND | I10: =+_xlfn.XLOOKUP(H10,Sheet1!C:C,Sheet1!B:B,"N/A",0) -> AD | J10: =+_xlfn.XLOOKUP(H10,Sheet1!C:C,Sheet1!D:D,"N/A",0) -> 020
A11: PSD | B11: Outbound | C11: Unitel (AGO) | D11: Angola | E11: 0.060004 | F11: =E11*1024 -> 61.444096 | G11: =_xlfn.MINIFS(F:F,D:D,D11,F:F,"<>0") -> 1.968128 | H11: =_xlfn.TEXTBEFORE(_xlfn.TEXTAFTER(C11,"("),")") -> AGO | I11: =+_xlfn.XLOOKUP(H11,Sheet1!C:C,Sheet1!B:B,"N/A",0) -> AO | J11: =+_xlfn.XLOOKUP(H11,Sheet1!C:C,Sheet1!D:D,"N/A",0) -> 024
A12: PSD | B12: Outbound | C12: Africell (AGO) | D12: Angola | E12: 0.001922 | F12: =E12*1024 -> 1.968128 | G12: =_xlfn.MINIFS(F:F,D:D,D12,F:F,"<>0") -> 1.968128 | H12: =_xlfn.TEXTBEFORE(_xlfn.TEXTAFTER(C12,"("),")") -> AGO | I12: =+_xlfn.XLOOKUP(H12,Sheet1!C:C,Sheet1!B:B,"N/A",0) -> AO | J12: =+_xlfn.XLOOKUP(H12,Sheet1!C:C,Sheet1!D:D,"N/A",0) -> 024
A13: PSD | B13: Outbound | C13: Liberty (AIA) | D13: Anguilla | E13: 0.003 | F13: =E13*1024 -> 3.072 | G13: =_xlfn.MINIFS(F:F,D:D,D13,F:F,"<>0") -> 3.072 | H13: =_xlfn.TEXTBEFORE(_xlfn.TEXTAFTER(C13,"("),")") -> AIA | I13: =+_xlfn.XLOOKUP(H13,Sheet1!C:C,Sheet1!B:B,"N/A",0) -> AI | J13: =+_xlfn.XLOOKUP(H13,Sheet1!C:C,Sheet1!D:D,"N/A",0) -> 660
A14: PSD | B14: Outbound | C14: Liberty (ATG) | D14: Antigua and Barbuda | E14: 0.003 | F14: =E14*1024 -> 3.072 | G14: =_xlfn.MINIFS(F:F,D:D,D14,F:F,"<>0") -> 3.072 | H14: =_xlfn.TEXTBEFORE(_xlfn.TEXTAFTER(C14,"("),")") -> ATG | I14: =+_xlfn.XLOOKUP(H14,Sheet1!C:C,Sheet1!B:B,"N/A",0) -> AG | J14: =+_xlfn.XLOOKUP(H14,Sheet1!C:C,Sheet1!D:D,"N/A",0) -> 028
... A71: PSD | B71: Outbound | C71: Airtel (TCD) | D71: Chad | E71: 0.0023 | F71: =E71*1024 -> 2.3552 | G71: =_xlfn.MINIFS(F:F,D:D,D71,F:F,"<>0") -> 2.3552 | H71: =_xlfn.TEXTBEFORE(_xlfn.TEXTAFTER(C71,"("),")") -> TCD | I71: =+_xlfn.XLOOKUP(H71,Sheet1!C:C,Sheet1!B:B,"N/A",0) -> TD | J71: =+_xlfn.XLOOKUP(H71,Sheet1!C:C,Sheet1!D:D,"N/A",0) -> 148
A72: PSD | B72: Outbound | C72: Jersey Telecoms (GBR) | D72: Channel Islands | E72: 0.0006 | F72: =E72*1024 -> 0.6144 | G72: =_xlfn.MINIFS(F:F,D:D,D72,F:F,"<>0") -> 0.6144 | H72: GGY | I72: GG | J72: =+_xlfn.XLOOKUP(H72,Sheet1!C:C,Sheet1!D:D,"N/A",0) -> 831
A73: PSD | B73: Outbound | C73: Sure Guernsey (GBR) | D73: Channel Islands | E73: 0.001408 | F73: =E73*1024 -> 1.441792 | G73: =_xlfn.MINIFS(F:F,D:D,D73,F:F,"<>0") -> 0.6144 | H73: JEY | I73: JE | J73: =+_xlfn.XLOOKUP(H73,Sheet1!C:C,Sheet1!D:D,"N/A",0) -> 832
A74: PSD | B74: Outbound | C74: Manx Telecom (GBR) | D74: Channel Islands | F74: =E74*1024 -> 0 | G74: =_xlfn.MINIFS(F:F,D:D,D74,F:F,"<>0") -> 0.6144 | H74: IMN | I74: IM | J74: =+_xlfn.XLOOKUP(H74,Sheet1!C:C,Sheet1!D:D,"N/A",0) -> 833
A75: PSD | B75: Outbound | C75: WOM (CHL) | D75: Chile | E75: 0.005 | F75: =E75*1024 -> 5.12 | G75: =_xlfn.MINIFS(F:F,D:D,D75,F:F,"<>0") -> 1.652736 | H75: =_xlfn.TEXTBEFORE(_xlfn.TEXTAFTER(C75,"("),")") -> CHL | I75: =+_xlfn.XLOOKUP(H75,Sheet1!C:C,Sheet1!B:B,"N/A",0) -> CL | J75: =+_xlfn.XLOOKUP(H75,Sheet1!C:C,Sheet1!D:D,"N/A",0) -> 152
A76: PSD | B76: Outbound | C76: Entel (CHL) | D76: Chile | E76: 0.002 | F76: =E76*1024 -> 2.048 | G76: =_xlfn.MINIFS(F:F,D:D,D76,F:F,"<>0") -> 1.652736 | H76: =_xlfn.TEXTBEFORE(_xlfn.TEXTAFTER(C76,"("),")") -> CHL | I76: =+_xlfn.XLOOKUP(H76,Sheet1!C:C,Sheet1!B:B,"N/A",0) -> CL | J76: =+_xlfn.XLOOKUP(H76,Sheet1!C:C,Sheet1!D:D,"N/A",0) -> 152
A77: PSD | B77: Outbound | C77: Telefonica (CHL) 1 | D77: Chile | E77: 0.001614 | F77: =E77*1024 -> 1.652736 | G77: =_xlfn.MINIFS(F:F,D:D,D77,F:F,"<>0") -> 1.652736 | H77: =_xlfn.TEXTBEFORE(_xlfn.TEXTAFTER(C77,"("),")") -> CHL | I77: =+_xlfn.XLOOKUP(H77,Sheet1!C:C,Sheet1!B:B,"N/A",0) -> CL | J77: =+_xlfn.XLOOKUP(H77,Sheet1!C:C,Sheet1!D:D,"N/A",0) -> 152
A78: PSD | B78: Outbound | C78: China Mobile (CHN) 1 | D78: China | E78: 0.001894 | F78: =E78*1024 -> 1.939456 | G78: =_xlfn.MINIFS(F:F,D:D,D78,F:F,"<>0") -> 1.69472 | H78: =_xlfn.TEXTBEFORE(_xlfn.TEXTAFTER(C78,"("),")") -> CHN | I78: =+_xlfn.XLOOKUP(H78,Sheet1!C:C,Sheet1!B:B,"N/A",0) -> CN | J78: =+_xlfn.XLOOKUP(H78,Sheet1!C:C,Sheet1!D:D,"N/A",0) -> 156
A79: PSD | B79: Outbound | C79: China Unicom (CHN) 1 | D79: China | E79: 0.001655 | F79: =E79*1024 -> 1.69472 | G79: =_xlfn.MINIFS(F:F,D:D,D79,F:F,"<>0") -> 1.69472 | H79: =_xlfn.TEXTBEFORE(_xlfn.TEXTAFTER(C79,"("),")") -> CHN | I79: =+_xlfn.XLOOKUP(H79,Sheet1!C:C,Sheet1!B:B,"N/A",0) -> CN | J79: =+_xlfn.XLOOKUP(H79,Sheet1!C:C,Sheet1!D:D,"N/A",0) -> 156
A80: PSD | B80: Outbound | C80: AMX (COL) | D80: Colombia | E80: 0.001 | F80: =E80*1024 -> 1.024 | G80: =_xlfn.MINIFS(F:F,D:D,D80,F:F,"<>0") -> 1.024 | H80: =_xlfn.TEXTBEFORE(_xlfn.TEXTAFTER(C80,"("),")") -> COL | I80: =+_xlfn.XLOOKUP(H80,Sheet1!C:C,Sheet1!B:B,"N/A",0) -> CO | J80: =+_xlfn.XLOOKUP(H80,Sheet1!C:C,Sheet1!D:D,"N/A",0) -> 170
A81: PSD | B81: Outbound | C81: Tigo (COL) 1 | D81: Colombia | E81: 0.002093 | F81: =E81*1024 -> 2.143232 | G81: =_xlfn.MINIFS(F:F,D:D,D81,F:F,"<>0") -> 1.024 | H81: =_xlfn.TEXTBEFORE(_xlfn.TEXTAFTER(C81,"("),")") -> COL | I81: =+_xlfn.XLOOKUP(H81,Sheet1!C:C,Sheet1!B:B,"N/A",0) -> CO | J81: =+_xlfn.XLOOKUP(H81,Sheet1!C:C,Sheet1!D:D,"N/A",0) -> 170
A82: PSD | B82: Outbound | C82: Telefonica (COL) | D82: Colombia | E82: 0.001613 | F82: =E82*1024 -> 1.651712 | G82: =_xlfn.MINIFS(F:F,D:D,D82,F:F,"<>0") -> 1.024 | H82: =_xlfn.TEXTBEFORE(_xlfn.TEXTAFTER(C82,"("),")") -> COL | I82: =+_xlfn.XLOOKUP(H82,Sheet1!C:C,Sheet1!B:B,"N/A",0) -> CO | J82: =+_xlfn.XLOOKUP(H82,Sheet1!C:C,Sheet1!D:D,"N/A",0) -> 170
A83: PSD | B83: Outbound | C83: Africell (COD) | D83: Congo Kinshasa | E83: 0.001921 | F83: =E83*1024 -> 1.967104 | G83: =_xlfn.MINIFS(F:F,D:D,D83,F:F,"<>0") -> 1.967104 | H83: =_xlfn.TEXTBEFORE(_xlfn.TEXTAFTER(C83,"("),")") -> COD | I83: =+_xlfn.XLOOKUP(H83,Sheet1!C:C,Sheet1!B:B,"N/A",0) -> CD | J83: =+_xlfn.XLOOKUP(H83,Sheet1!C:C,Sheet1!D:D,"N/A",0) -> 180
A84: PSD | B84: Outbound | C84: Vodafone (COD) | D84: Congo Kinshasa | E84: 0.066911 | F84: =E84*1024 -> 68.516864 | G84: =_xlfn.MINIFS(F:F,D:D,D84,F:F,"<>0") -> 1.967104 | H84: =_xlfn.TEXTBEFORE(_xlfn.TEXTAFTER(C84,"("),")") -> COD | I84: =+_xlfn.XLOOKUP(H84,Sheet1!C:C,Sheet1!B:B,"N/A",0) -> CD | J84: =+_xlfn.XLOOKUP(H84,Sheet1!C:C,Sheet1!D:D,"N/A",0) -> 180
A85: PSD | B85: Outbound | C85: ICE (CRI) | D85: Costa Rica | E85: 0.001 | F85: =E85*1024 -> 1.024 | G85: =_xlfn.MINIFS(F:F,D:D,D85,F:F,"<>0") -> 1.024 | H85: =_xlfn.TEXTBEFORE(_xlfn.TEXTAFTER(C85,"("),")") -> CRI | I85: =+_xlfn.XLOOKUP(H85,Sheet1!C:C,Sheet1!B:B,"N/A",0) -> CR | J85: =+_xlfn.XLOOKUP(H85,Sheet1!C:C,Sheet1!D:D,"N/A",0) -> 188
A86: PSD | B86: Outbound | C86: Liberty (CRI) | D86: Costa Rica | E86: 0.001613 | F86: =E86*1024 -> 1.651712 | G86: =_xlfn.MINIFS(F:F,D:D,D86,F:F,"<>0") -> 1.024 | H86: =_xlfn.TEXTBEFORE(_xlfn.TEXTAFTER(C86,"("),")") -> CRI | I86: =+_xlfn.XLOOKUP(H86,Sheet1!C:C,Sheet1!B:B,"N/A",0) -> CR | J86: =+_xlfn.XLOOKUP(H86,Sheet1!C:C,Sheet1!D:D,"N/A",0) -> 188
A87: PSD | B87: Outbound | C87: DT (HRV) | D87: Croatia | F87: =E87*1024 -> 0 | G87: =_xlfn.MINIFS(F:F,D:D,D87,F:F,"<>0") -> 0 | H87: =_xlfn.TEXTBEFORE(_xlfn.TEXTAFTER(C87,"("),")") -> HRV | I87: =+_xlfn.XLOOKUP(H87,Sheet1!C:C,Sheet1!B:B,"N/A",0) -> HR | J87: =+_xlfn.XLOOKUP(H87,Sheet1!C:C,Sheet1!D:D,"N/A",0) -> 191
A88: PSD | B88: Outbound | C88: Cubacel (CUB) | D88: Cuba | E88: 0.056095 | F88: =E88*1024 -> 57.44128 | G88: =_xlfn.MINIFS(F:F,D:D,D88,F:F,"<>0") -> 57.44128 | H88: =_xlfn.TEXTBEFORE(_xlfn.TEXTAFTER(C88,"("),")") -> CUB | I88: =+_xlfn.XLOOKUP(H88,Sheet1!C:C,Sheet1!B:B,"N/A",0) -> CU | J88: =+_xlfn.XLOOKUP(H88,Sheet1!C:C,Sheet1!D:D,"N/A",0) -> 192
A89: PSD | B89: Outbound | C89: PrimeTel (CYP) | D89: Cyprus | E89: 0.000475 | F89: =E89*1024 -> 0.4864 | G89: =_xlfn.MINIFS(F:F,D:D,D89,F:F,"<>0") -> 0.256 | H89: =_xlfn.TEXTBEFORE(_xlfn.TEXTAFTER(C89,"("),")") -> CYP | I89: =+_xlfn.XLOOKUP(H89,Sheet1!C:C,Sheet1!B:B,"N/A",0) -> CY | J89: =+_xlfn.XLOOKUP(H89,Sheet1!C:C,Sheet1!D:D,"N/A",0) -> 196
A90: PSD | B90: Outbound | C90: Epic (CYP) | D90: Cyprus | E90: 0.000573 | F90: =E90*1024 -> 0.586752 | G90: =_xlfn.MINIFS(F:F,D:D,D90,F:F,"<>0") -> 0.256 | H90: =_xlfn.TEXTBEFORE(_xlfn.TEXTAFTER(C90,"("),")") -> CYP | I90: =+_xlfn.XLOOKUP(H90,Sheet1!C:C,Sheet1!B:B,"N/A",0) -> CY | J90: =+_xlfn.XLOOKUP(H90,Sheet1!C:C,Sheet1!D:D,"N/A",0) -> 196
A91: PSD | B91: Outbound | C91: CYTA (CYP) | D91: Cyprus | E91: 0.00025 | F91: =E91*1024 -> 0.256 | G91: =_xlfn.MINIFS(F:F,D:D,D91,F:F,"<>0") -> 0.256 | H91: =_xlfn.TEXTBEFORE(_xlfn.TEXTAFTER(C91,"("),")") -> CYP | I91: =+_xlfn.XLOOKUP(H91,Sheet1!C:C,Sheet1!B:B,"N/A",0) -> CY | J91: =+_xlfn.XLOOKUP(H91,Sheet1!C:C,Sheet1!D:D,"N/A",0) -> 196
A92: PSD | B92: Outbound | C92: Vodafone (CZE) | D92: Czech Republic | E92: 0.000766 | F92: =E92*1024 -> 0.784384 | G92: =_xlfn.MINIFS(F:F,D:D,D92,F:F,"<>0") -> 0.530432 | H92: =_xlfn.TEXTBEFORE(_xlfn.TEXTAFTER(C92,"("),")") -> CZE | I92: =+_xlfn.XLOOKUP(H92,Sheet1!C:C,Sheet1!B:B,"N/A",0) -> CZ | J92: =+_xlfn.XLOOKUP(H92,Sheet1!C:C,Sheet1!D:D,"N/A",0) -> 203
A93: PSD | B93: Outbound | C93: DT (CZE) | D93: Czech Republic | E93: 0.00086 | F93: =E93*1024 -> 0.88064 | G93: =_xlfn.MINIFS(F:F,D:D,D93,F:F,"<>0") -> 0.530432 | H93: =_xlfn.TEXTBEFORE(_xlfn.TEXTAFTER(C93,"("),")") -> CZE | I93: =+_xlfn.XLOOKUP(H93,Sheet1!C:C,Sheet1!B:B,"N/A",0) -> CZ | J93: =+_xlfn.XLOOKUP(H93,Sheet1!C:C,Sheet1!D:D,"N/A",0) -> 203
A94: PSD | B94: Outbound | C94: Cetin (CZE) | D94: Czech Republic | E94: 0.000518 | F94: =E94*1024 -> 0.530432 | G94: =_xlfn.MINIFS(F:F,D:D,D94,F:F,"<>0") -> 0.530432 | H94: =_xlfn.TEXTBEFORE(_xlfn.TEXTAFTER(C94,"("),")") -> CZE | I94: =+_xlfn.XLOOKUP(H94,Sheet1!C:C,Sheet1!B:B,"N/A",0) -> CZ | J94: =+_xlfn.XLOOKUP(H94,Sheet1!C:C,Sheet1!D:D,"N/A",0) -> 203
A95: PSD | B95: Outbound | C95: Telenor (DNK) 1 | D95: Denmark | E95: 0.000255 | F95: =E95*1024 -> 0.26112 | G95: =_xlfn.MINIFS(F:F,D:D,D95,F:F,"<>0") -> 0.26112 | H95: =_xlfn.TEXTBEFORE(_xlfn.TEXTAFTER(C95,"("),")") -> DNK | I95: =+_xlfn.XLOOKUP(H95,Sheet1!C:C,Sheet1!B:B,"N/A",0) -> DK | J95: =+_xlfn.XLOOKUP(H95,Sheet1!C:C,Sheet1!D:D,"N/A",0) -> 208
A96: PSD | B96: Outbound | C96: TDC (DNK) | D96: Denmark | E96: 0.000314 | F96: =E96*1024 -> 0.321536 | G96: =_xlfn.MINIFS(F:F,D:D,D96,F:F,"<>0") -> 0.26112 | H96: =_xlfn.TEXTBEFORE(_xlfn.TEXTAFTER(C96,"("),")") -> DNK | I96: =+_xlfn.XLOOKUP(H96,Sheet1!C:C,Sheet1!B:B,"N/A",0) -> DK | J96: =+_xlfn.XLOOKUP(H96,Sheet1!C:C,Sheet1!D:D,"N/A",0) -> 208
...

Sheet Sheet1
A1: Country | B1: Alpha-2 code | C1: Alpha-3 code | D1: Numeric
A2: Afghanistan | B2: AF | C2: AFG | D2: 004
A3: Albania | B3: AL | C3: ALB | D3: 008
A4: Algeria | B4: DZ | C4: DZA | D4: 012
A5: American Samoa | B5: AS | C5: ASM | D5: 016
A6: Andorra | B6: AD | C6: AND | D6: 020
A7: Angola | B7: AO | C7: AGO | D7: 024
A8: Anguilla | B8: AI | C8: AIA | D8: 660
A9: Antarctica | B9: AQ | C9: ATA | D9: 010
A10: Antigua and Barbuda | B10: AG | C10: ATG | D10: 028
A11: Argentina | B11: AR | C11: ARG | D11: 032
A12: Armenia | B12: AM | C12: ARM | D12: 051
... A250: Åland Islands | B250: AX | C250: ALA | D250: 248
A251: Kosovo | B251: XK | C251: XKX
